Workbook
Name FG_GolesLocal: WORLDCUP!$AC$4:$AC$97
Name FG_GolesVisitante: WORLDCUP!$AD$4:$AD$97
Name FGLocal: WORLDCUP!$AA$4:$AA$97
Name FGVisitante: WORLDCUP!$AF$4:$AF$97
Name Ganador: WORLDCUP!$D$4:$D$97
Name Part1Empate1L: WORLDCUP!$E$4:$E$97
Name Part1Empate1V: WORLDCUP!$F$4:$F$97
Name Part1Empate2L: WORLDCUP!$H$4:$H$97
Name Part1Empate2V: WORLDCUP!$I$4:$I$97
Name Part1Empate3L: WORLDCUP!$K$4:$K$97
Name Part1Empate3V: WORLDCUP!$L$4:$L$97
Name Part2Empate4L: WORLDCUP!$N$4:$N$97
Name Part2Empate4V: WORLDCUP!$O$4:$O$97
Name Part2Empate5L: WORLDCUP!$Q$4:$Q$97
Name Part2Empate5V: WORLDCUP!$R$4:$R$97
Name Part2Empate6L: WORLDCUP!$T$4:$T$97
Name Part2Empate6V: WORLDCUP!$U$4:$U$97

Sheet Home
B3: =Idiomas!D8 -> XXIII Mundial USA/MEX/CAN 2026
C5: ="📋 "&Idiomas!D7 -> 📋 Selecciona idioma
C6: Español | K6: =Idiomas!D4 -> Introducir resultados
C7: ="🕒 "&Idiomas!D15 -> 🕒 Selecciona horario
C8: España | K8: Fixture
C9: ="✍️ "&Idiomas!D46 -> ✍️ Escribe tu nombre
C10: =Idiomas!D45 -> Nombre | K10: Help
E16: =HYPERLINK(Idiomas!D10,Idiomas!D5) -> Si quieres organizar una porra (quiniela) con tu grupo puedes descargar el archivo de adminsitrador desde el enlace de abajo
E17: =HYPERLINK(Idiomas!D10,Idiomas!D9) -> ▼ Descargar Excel Administrador Porra ▼ | K17: Video►Tutorial
E21: Share:
E22: Whatsapp | F22: Telegram | G22: Mail | H22: X | I22: in
K23: © Miguel Angel Tejero. 2026 | L23: =+Idiomas!D12 -> Donar
B24: =Idiomas!D11 -> *Versión provisional hasta que se conozcan todos los participantes en marzo 2026
AGA59: {=IF(AND($BZ$59:$BZ$60=$BZ$59,$BZ$60<>$BZ$61,$BZ$61<>$BZ$62,$BZ$62<>$BZ$63,$BZ$63:$BZ$64=$BZ$63,$CB$59:$CB$60=$CB$59,$CB$63:$CB$64=$CB$63,$CC$59:$CC$60=$CC$59,$CC$63<>$CC$64,$CD$59:$CD$60=$CD$59),1,0)} -> 0 | AGB59: {=IF(AND($BZ$59:$BZ$60=$BZ$59,$BZ$60<>$BZ$61,$BZ$61<>$BZ$62,$BZ$62<>$BZ$63,$BZ$63:$BZ$64=$BZ$63,$CB$59:$CB$60=$CB$59,$CB$63:$CB$64=$CB$63,$CC$59<>$CC$60,$CC$63:$CC$64=$CC$63,$CD$63:$CD$64=$CD$63),1,0)} -> 0 | AGC59: {=IF(AND($BZ$59:$BZ$60=$BZ$59,$BZ$60<>$BZ$61,$BZ$61<>$BZ$62,$BZ$62<>$BZ$63,$BZ$63:$BZ$64=$BZ$63,$CB$59:$CB$60=$CB$59,$CB$63:$CB$64=$CB$63,$CC$59<>$CC$60,$CC$63<>$CC$64),1,0)} -> 0
CC60: 5 | AGA60: {=IF(AND($BZ$59:$BZ$60=$BZ$60,$BZ$60<>$BZ$61,$BZ$61<>$BZ$62,$BZ$62<>$BZ$63,$BZ$63:$BZ$64=$BZ$63,$CB$59:$CB$60=$CB$60,$CB$63:$CB$64=$CB$63,$CC$59:$CC$60=$CC$60,$CC$63<>$CC$64,$CD$59:$CD$60=$CD$60),1,0)} -> 0 | AGB60: {=IF(AND($BZ$59:$BZ$60=$BZ$60,$BZ$60<>$BZ$61,$BZ$61<>$BZ$62,$BZ$62<>$BZ$63,$BZ$63:$BZ$64=$BZ$63,$CB$59:$CB$60=$CB$60,$CB$63:$CB$64=$CB$63,$CC$59<>$CC$60,$CC$63:$CC$64=$CC$63,$CD$63:$CD$64=$CD$63),1,0)} -> 0 | AGC60: {=IF(AND($BZ$59:$BZ$60=$BZ$60,$BZ$60<>$BZ$61,$BZ$61<>$BZ$62,$BZ$62<>$BZ$63,$BZ$63:$BZ$64=$BZ$63,$CB$59:$CB$60=$CB$60,$CB$63:$CB$64=$CB$63,$CC$59<>$CC$60,$CC$63<>$CC$64),1,0)} -> 0
JW61: {=IF(AND($BZ$59:$BZ$64=$BZ$61,$CB$59:$CB$64=$CB$61,$CC$59:$CC$60=$CC$60,$CC$60<>$CC$61,$CC$61:$CC$64=$CC$61,$CD$59:$CD$60=$CD$60,$CD$61<>$CD$62,$CD$62:$CD$64=$CD$62),1,0)} -> 0 | AGA61: {=IF(AND($BZ$59:$BZ$60=$BZ$60,$BZ$60<>$BZ$61,$BZ$61<>$BZ$62,$BZ$62<>$BZ$63,$BZ$63:$BZ$64=$BZ$63,$CB$59:$CB$60=$CB$60,$CB$63:$CB$64=$CB$63,$CC$59:$CC$60=$CC$60,$CC$63<>$CC$64,$CD$59:$CD$60=$CD$60),1,0)} -> 0 | AGB61: {=IF(AND($BZ$59:$BZ$60=$BZ$60,$BZ$60<>$BZ$61,$BZ$61<>$BZ$62,$BZ$62<>$BZ$63,$BZ$63:$BZ$64=$BZ$63,$CB$59:$CB$60=$CB$60,$CB$63:$CB$64=$CB$63,$CC$59<>$CC$60,$CC$63:$CC$64=$CC$63,$CD$63:$CD$64=$CD$63),1,0)} -> 0 | AGC61: {=IF(AND($BZ$59:$BZ$60=$BZ$60,$BZ$60<>$BZ$61,$BZ$61<>$BZ$62,$BZ$62<>$BZ$63,$BZ$63:$BZ$64=$BZ$63,$CB$59:$CB$60=$CB$60,$CB$63:$CB$64=$CB$63,$CC$59<>$CC$60,$CC$63<>$CC$64),1,0)} -> 0
JW62: {=IF(AND($BZ$59:$BZ$64=$BZ$62,$CB$59:$CB$64=$CB$62,$CC$59:$CC$60=$CC$60,$CC$60<>$CC$61,$CC$61:$CC$64=$CC$62,$CD$59:$CD$60=$CD$60,$CD$61<>$CD$62,$CD$62:$CD$64=$CD$62),1,0)} -> 0 | AFW62: {=IF(AND($BZ$59:$BZ$60=$BZ$60,$BZ$60<>$BZ$61,$BZ$61<>$BZ$62,$BZ$62:$BZ$64=$BZ$62,$CB$59:$CB$60=$CB$60,$CB$62:$CB$64=$CB$62,$CC$59<>$CC$60,$CC$62:$CC$64=$CC$62,$CD$62:$CD$64=$CD$62),1,0)} -> 0 | AFX62: {=IF(AND($BZ$59:$BZ$60=$BZ$60,$BZ$60<>$BZ$61,$BZ$61<>$BZ$62,$BZ$62:$BZ$64=$BZ$62,$CB$59:$CB$60=$CB$60,$CB$62:$CB$64=$CB$62,$CC$59<>$CC$60,$CC$62:$CC$64=$CC$62,$CD$62:$CD$64=$CD$62),1,0)} -> 0 | AGA62: {=IF(AND($BZ$59:$BZ$60=$BZ$60,$BZ$60<>$BZ$61,$BZ$61<>$BZ$62,$BZ$62<>$BZ$63,$BZ$63:$BZ$64=$BZ$63,$CB$59:$CB$60=$CB$60,$CB$63:$CB$64=$CB$63,$CC$59:$CC$60=$CC$60,$CC$63<>$CC$64,$CD$59:$CD$60=$CD$60),1,0)} -> 0 | AGB62: {=IF(AND($BZ$59:$BZ$60=$BZ$60,$BZ$60<>$BZ$61,$BZ$61<>$BZ$62,$BZ$62<>$BZ$63,$BZ$63:$BZ$64=$BZ$63,$CB$59:$CB$60=$CB$60,$CB$63:$CB$64=$CB$63,$CC$59<>$CC$60,$CC$63:$CC$64=$CC$63,$CD$63:$CD$64=$CD$63),1,0)} -> 0 | AGC62: {=IF(AND($BZ$59:$BZ$60=$BZ$60,$BZ$60<>$BZ$61,$BZ$61<>$BZ$62,$BZ$62<>$BZ$63,$BZ$63:$BZ$64=$BZ$63,$CB$59:$CB$60=$CB$60,$CB$63:$CB$64=$CB$63,$CC$59<>$CC$60,$CC$63<>$CC$64),1,0)} -> 0
JW63: {=IF(AND($BZ$59:$BZ$64=$BZ$63,$CB$59:$CB$64=$CB$63,$CC$59:$CC$60=$CC$60,$CC$60<>$CC$61,$CC$61:$CC$64=$CC$62,$CD$59:$CD$60=$CD$60,$CD$61<>$CD$62,$CD$62:$CD$64=$CD$63),1,0)} -> 0 | AFW63: {=IF(AND($BZ$59:$BZ$60=$BZ$60,$BZ$60<>$BZ$61,$BZ$61<>$BZ$62,$BZ$62:$BZ$64=$BZ$63,$CB$59:$CB$60=$CB$60,$CB$62:$CB$64=$CB$63,$CC$59<>$CC$60,$CC$62:$CC$64=$CC$63,$CD$62:$CD$64=$CD$63),1,0)} -> 0 | AFX63: {=IF(AND($BZ$59:$BZ$60=$BZ$60,$BZ$60<>$BZ$61,$BZ$61<>$BZ$62,$BZ$62:$BZ$64=$BZ$63,$CB$59:$CB$60=$CB$60,$CB$62:$CB$64=$CB$63,$CC$59<>$CC$60,$CC$62:$CC$64=$CC$63,$CD$62:$CD$64=$CD$63),1,0)} -> 0 | AGA63: {=IF(AND($BZ$59:$BZ$60=$BZ$60,$BZ$60<>$BZ$61,$BZ$61<>$BZ$62,$BZ$62<>$BZ$63,$BZ$63:$BZ$64=$BZ$63,$CB$59:$CB$60=$CB$60,$CB$63:$CB$64=$CB$63,$CC$59:$CC$60=$CC$60,$CC$63<>$CC$64,$CD$59:$CD$60=$CD$60),1,0)} -> 0 | AGB63: {=IF(AND($BZ$59:$BZ$60=$BZ$60,$BZ$60<>$BZ$61,$BZ$61<>$BZ$62,$BZ$62<>$BZ$63,$BZ$63:$BZ$64=$BZ$63,$CB$59:$CB$60=$CB$60,$CB$63:$CB$64=$CB$63,$CC$59<>$CC$60,$CC$63:$CC$64=$CC$63,$CD$63:$CD$64=$CD$63),1,0)} -> 0 | AGC63: {=IF(AND($BZ$59:$BZ$60=$BZ$60,$BZ$60<>$BZ$61,$BZ$61<>$BZ$62,$BZ$62<>$BZ$63,$BZ$63:$BZ$64=$BZ$63,$CB$59:$CB$60=$CB$60,$CB$63:$CB$64=$CB$63,$CC$59<>$CC$60,$CC$63<>$CC$64),1,0)} -> 0
CC64: 1 | JW64: {=IF(AND($BZ$59:$BZ$64=$BZ$64,$CB$59:$CB$64=$CB$64,$CC$59:$CC$60=$CC$60,$CC$60<>$CC$61,$CC$61:$CC$64=$CC$62,$CD$59:$CD$60=$CD$60,$CD$61<>$CD$62,$CD$62:$CD$64=$CD$64),1,0)} -> 0 | AFW64: {=IF(AND($BZ$59:$BZ$60=$BZ$60,$BZ$60<>$BZ$61,$BZ$61<>$BZ$62,$BZ$62:$BZ$64=$BZ$64,$CB$59:$CB$60=$CB$60,$CB$62:$CB$64=$CB$64,$CC$59<>$CC$60,$CC$62:$CC$64=$CC$64,$CD$62:$CD$64=$CD$64),1,0)} -> 0 | AFX64: {=IF(AND($BZ$59:$BZ$60=$BZ$60,$BZ$60<>$BZ$61,$BZ$61<>$BZ$62,$BZ$62:$BZ$64=$BZ$64,$CB$59:$CB$60=$CB$60,$CB$62:$CB$64=$CB$64,$CC$59<>$CC$60,$CC$62:$CC$64=$CC$64,$CD$62:$CD$64=$CD$64),1,0)} -> 0 | AGA64: {=IF(AND($BZ$59:$BZ$60=$BZ$60,$BZ$60<>$BZ$61,$BZ$61<>$BZ$62,$BZ$62<>$BZ$63,$BZ$63:$BZ$64=$BZ$64,$CB$59:$CB$60=$CB$60,$CB$63:$CB$64=$CB$64,$CC$59:$CC$60=$CC$60,$CC$63<>$CC$64,$CD$59:$CD$60=$CD$60),1,0)} -> 0 | AGB64: {=IF(AND($BZ$59:$BZ$60=$BZ$60,$BZ$60<>$BZ$61,$BZ$61<>$BZ$62,$BZ$62<>$BZ$63,$BZ$63:$BZ$64=$BZ$64,$CB$59:$CB$60=$CB$60,$CB$63:$CB$64=$CB$64,$CC$59<>$CC$60,$CC$63:$CC$64=$CC$64,$CD$63:$CD$64=$CD$64),1,0)} -> 0 | AGC64: {=IF(AND($BZ$59:$BZ$60=$BZ$60,$BZ$60<>$BZ$61,$BZ$61<>$BZ$62,$BZ$62<>$BZ$63,$BZ$63:$BZ$64=$BZ$64,$CB$59:$CB$60=$CB$60,$CB$63:$CB$64=$CB$64,$CC$59<>$CC$60,$CC$63<>$CC$64),1,0)} -> 0 | AGU64: {=IF(AND($BZ$59<>$BZ$60,$BZ$60:$BZ$64=$BZ$64,$CB$60:$CB$64=$CB$64,$CC$60<>$CC$61,$CC$61<>$CC$62,$CC$62<>$CC$63,$CC$63:$CC$64=$CC$64,$CD$63:$CD$64=$CD$64),1,0)} -> 0 | AGV64: {=IF(AND($BZ$59<>$BZ$60,$BZ$60:$BZ$64=$BZ$64,$CB$60:$CB$64=$CB$64,$CC$60<>$CC$61,$CC$61<>$CC$62,$CC$62<>$CC$63,$CC$63<>$CC$64),1,0)} -> 0

Sheet WORLDCUP
W1: =Idiomas!D8 -> XXIII Mundial USA/MEX/CAN 2026 | AL1: =HYPERLINK(Idiomas!D10,Idiomas!D9) -> ▼ Descargar Excel Administrador Porra ▼ | AV1: Video►Tutorial | DL1: Horarios!$P$3
D3: WINNER | E3: Empate1L | F3: Empate1V | H3: Empate2L | I3: Empate2V | K3: Empate3L | L3: Empate3V | N3: Empate4L | O3: Empate4V | Q3: Empate5L | R3: Empate5V | T3: Empate6L | U3: Empate6V | X3: =Idiomas!D17 -> Fecha | Y3: =Idiomas!D18 -> Hora | Z3: =Idiomas!D19 -> Jor. | AA3: =Idiomas!D20 -> Casa | AC3: =Idiomas!D21 -> Gol | AD3: =Idiomas!D21 -> Gol | AF3: =Idiomas!D22 -> Fuera | AJ3: =Idiomas!D23 -> Grupo | AV3: =Idiomas!D24 -> ¡EMPATE! Puedes seleccionar el orden de los empatados. | AY3: =Idiomas!D72 -> ¿Hay equipos penalizados? | AZ3: No | MCA3: matejero
A4: NombreEquipo | B4: A | C4: =COUNTIF(Equipos!$C$2:$C$49,WORLDCUP!B4) -> 4 | D4: =IF(OR(AC4="",AD4=""),"Pendiente",IF(AC4>AD4,"Local",IF(AC4<AD4,"Visitante","Empate"))) -> Local | E4: =IF(D4="Pendiente","-",INDEX($BR$6:$BR$53,MATCH($AA4,$BD$6:$BD$53,0))) -> - | F4: =IF(D4="Pendiente","-",INDEX($BR$6:$BR$53,MATCH($AF4,$BD$6:$BD$53,0))) -> - | H4: =IF(D4="Pendiente","-",INDEX($BX$6:$BX$53,MATCH($AA4,$BD$6:$BD$53,0))) -> - | I4: =IF(D4="Pendiente","-",INDEX($BX$6:$BX$53,MATCH($AF4,$BD$6:$BD$53,0))) -> - | K4: =IF(D4="Pendiente","-",INDEX($CC$6:$CC$53,MATCH($AA4,$BD$6:$BD$53,0))) -> - | L4: =IF(D4="Pendiente","-",INDEX($CC$6:$CC$53,MATCH($AF4,$BD$6:$BD$53,0))) -> - | N4: =IF(D4="Pendiente","-",INDEX($CF$6:$CF$53,MATCH($AA4,$BD$6:$BD$53,0))) -> - | O4: =IF(D4="Pendiente","-",INDEX($CF$6:$CF$53,MATCH($AF4,$BD$6:$BD$53,0))) -> - | Q4: =IF(D4="Pendiente","-",INDEX($CL$6:$CL$53,MATCH($AA4,$BD$6:$BD$53,0))) -> - | R4: =IF(D4="Pendiente","-",INDEX($CL$6:$CL$53,MATCH($AF4,$BD$6:$BD$53,0))) -> - | T4: =IF(D4="Pendiente","-",INDEX($CQ$6:$CQ$53,MATCH($AA4,$BD$6:$BD$53,0))) -> - | U4: =IF(D4="Pendiente","-",INDEX($CQ$6:$CQ$53,MATCH($AF4,$BD$6:$BD$53,0))) -> - | W4: A | X4: =Horarios!C4 -> 46184.875 | Y4: =Horarios!C4 -> 46184.875 | Z4: =Idiomas!D61 -> J1 | AA4: =+A5 -> México | AB4: =+INDEX(Equipos!$L$2:$L$49,MATCH(WORLDCUP!AA4,Equipos!$K$2:$K$49,0)) -> 🇲🇽 | AC4: 2 | AD4: 1 | AE4: =+INDEX(Equipos!$L$2:$L$49,MATCH(WORLDCUP!AF4,Equipos!$K$2:$K$49,0)) -> 🇿🇦 | AF4: =A6 -> Sudáfrica | AG4: =IF(NOT(OR(ISBLANK(AC4),ISBLANK(AD4))),1,0) -> 1 | AH4: 1 | AJ4: =CONCATENATE(AJ3," ",B4) -> Grupo A | AV4: =IF(AU5>0,$AV$3,"") | DA4: En Grupos por bombo, en terceros por orden alfa
A5: =+Equipos!B2 -> México | D5: =IF(OR(AC5="",AD5=""),"Pendiente",IF(AC5>AD5,"Local",IF(AC5<AD5,"Visitante","Empate"))) -> Empate | E5: =IF(D5="Pendiente","-",INDEX($BR$6:$BR$53,MATCH($AA5,$BD$6:$BD$53,0))) -> P.3 (2) | F5: =IF(D5="Pendiente","-",INDEX($BR$6:$BR$53,MATCH($AF5,$BD$6:$BD$53,0))) -> P.3 (2) | H5: =IF(D5="Pendiente","-",INDEX($BX$6:$BX$53,MATCH($AA5,$BD$6:$BD$53,0))) -> P.3 (2) | I5: =IF(D5="Pendiente","-",INDEX($BX$6:$BX$53,MATCH($AF5,$BD$6:$BD$53,0))) -> P.3 (2) | K5: =IF(D5="Pendiente","-",INDEX($CC$6:$CC$53,MATCH($AA5,$BD$6:$BD$53,0))) -> P.3 (2) | L5: =IF(D5="Pendiente","-",INDEX($CC$6:$CC$53,MATCH($AF5,$BD$6:$BD$53,0))) -> P.3 (2) | N5: =IF(D5="Pendiente","-",INDEX($CF$6:$CF$53,MATCH($AA5,$BD$6:$BD$53,0))) -> P.3 (2) | O5: =IF(D5="Pendiente","-",INDEX($CF$6:$CF$53,MATCH($AF5,$BD$6:$BD$53,0))) -> P.3 (2) | Q5: =IF(D5="Pendiente","-",INDEX($CL$6:$CL$53,MATCH($AA5,$BD$6:$BD$53,0))) -> P.3 (2) | R5: =IF(D5="Pendiente","-",INDEX($CL$6:$CL$53,MATCH($AF5,$BD$6:$BD$53,0))) -> P.3 (2) | T5: =IF(D5="Pendiente","-",INDEX($CQ$6:$CQ$53,MATCH($AA5,$BD$6:$BD$53,0))) -> P.3 (2) | U5: =IF(D5="Pendiente","-",INDEX($CQ$6:$CQ$53,MATCH($AF5,$BD$6:$BD$53,0))) -> P.3 (2) | X5: =Horarios!C5 -> 46185.167 | Y5: =Horarios!C5 -> 46185.167 | Z5: =$Z$4 -> J1 | AA5: =A7 -> Corea del Sur | AB5: =+INDEX(Equipos!$L$2:$L$49,MATCH(WORLDCUP!AA5,Equipos!$K$2:$K$49,0)) -> 🇰🇷 | AC5: 1 | AD5: 1 | AE5: =+INDEX(Equipos!$L$2:$L$49,MATCH(WORLDCUP!AF5,Equipos!$K$2:$K$49,0)) | AF5: =A8 -> PO D: DEN/MKD/CZE/IRL | AG5: =IF(NOT(OR(ISBLANK(AC5),ISBLANK(AD5))),1,0) -> 1 | AH5: 2 | AJ5: =Idiomas!D51 -> Pos | AL5: =Idiomas!D52 -> Selección | AM5: =Idiomas!D53 -> Pts | AN5: =Idiomas!D54 -> J | AO5: =Idiomas!D55 -> G | AP5: =Idiomas!D56 -> E | AQ5: =Idiomas!D57 -> P | AR5: =Idiomas!D58 -> GF | AS5: =Idiomas!D59 -> GC | AT5: =Idiomas!D60 -> DG | AU5: =COUNTIF(AU6:AU9,">1") -> 0 | AY5: =AL5 -> Selección | AZ5: =+Idiomas!$D$67 -> Puntos penalizados | BC5: =Idiomas!D23 -> Grupo | BD5: =Idiomas!D52 -> Selección | BE5: =+AM5 -> Pts | BF5: =+AN5 -> J | BG5: =+AO5 -> G | BH5: =+AP5 -> E | BI5: =+AQ5 -> P | BJ5: =+AR5 -> GF | BK5: =+AS5 -> GC | BL5: =+AT5 -> DG | BM5: PosF1 | BN5: PosF3 | BP5: PTS | BQ5: Posicion1 | BR5: Empate1 | BS5: PGPart1 | BT5: PEPart1 | BU5: PPPart1 | BV5: PTSPart1 | BW5: Posicion2 | BX5: Empate2 | BY5: GFPart1 | BZ5: GCPart1 | CA5: DGPArt1 | CB5: Posicion3 | CC5: Empate3 | CD5: GFPart1 | CE5: Posicion4 | CF5: Empate4 | CG5: PGPart2 | CH5: PEPart2 | CI5: PPPart2 | CJ5: PTSPart2 | CK5: Posicion5 | CL5: Empate5 | CM5: GFPart2 | CN5: GCPart2 | CO5: DGPArt2 | CP5: Posicion6 | CQ5: Empate6 | CR5: GFPart2 | CS5: Posicion7 | CT5: Empate7 | CU5: DG | CV5: Posicion8 | CW5: Empate8 | CX5: GF | CY5: Posicion9 | CZ5: Empate9 | DA5: OrdenAlfa/Bombo | DB5: PosicionF1 | DD5: PosicionF2 | DE5: Criterio/Fila | DF5: PosicionF3 | DH5: POS | DI5: Numero Partidos disputados grupo | DJ5: CANT | DK5: CONCAT | DL5: DESEMPATE EN SELECTOR | DN5: POSGRUPO | DO5: PAIS
A6: =+Equipos!B3 -> Sudáfrica | D6: =IF(OR(AC6="",AD6=""),"Pendiente",IF(AC6>AD6,"Local",IF(AC6<AD6,"Visitante","Empate"))) -> Empate | E6: =IF(D6="Pendiente","-",INDEX($BR$6:$BR$53,MATCH($AA6,$BD$6:$BD$53,0))) -> P.3 (2) | F6: =IF(D6="Pendiente","-",INDEX($BR$6:$BR$53,MATCH($AF6,$BD$6:$BD$53,0))) -> - | H6: =IF(D6="Pendiente","-",INDEX($BX$6:$BX$53,MATCH($AA6,$BD$6:$BD$53,0))) -> P.3 (2) | I6: =IF(D6="Pendiente","-",INDEX($BX$6:$BX$53,MATCH($AF6,$BD$6:$BD$53,0))) -> - | K6: =IF(D6="Pendiente","-",INDEX($CC$6:$CC$53,MATCH($AA6,$BD$6:$BD$53,0))) -> P.3 (2) | L6: =IF(D6="Pendiente","-",INDEX($CC$6:$CC$53,MATCH($AF6,$BD$6:$BD$53,0))) -> - | N6: =IF(D6="Pendiente","-",INDEX($CF$6:$CF$53,MATCH($AA6,$BD$6:$BD$53,0))) -> P.3 (2) | O6: =IF(D6="Pendiente","-",INDEX($CF$6:$CF$53,MATCH($AF6,$BD$6:$BD$53,0))) -> - | Q6: =IF(D6="Pendiente","-",INDEX($CL$6:$CL$53,MATCH($AA6,$BD$6:$BD$53,0))) -> P.3 (2) | R6: =IF(D6="Pendiente","-",INDEX($CL$6:$CL$53,MATCH($AF6,$BD$6:$BD$53,0))) -> - | T6: =IF(D6="Pendiente","-",INDEX($CQ$6:$CQ$53,MATCH($AA6,$BD$6:$BD$53,0))) -> P.3 (2) | U6: =IF(D6="Pendiente","-",INDEX($CQ$6:$CQ$53,MATCH($AF6,$BD$6:$BD$53,0))) -> - | X6: =Horarios!C6 -> 46191.75 | Y6: =Horarios!C6 -> 46191.75 | Z6: =Idiomas!D62 -> J2 | AA6: =A8 -> PO D: DEN/MKD/CZE/IRL | AB6: =+INDEX(Equipos!$L$2:$L$49,MATCH(WORLDCUP!AA6,Equipos!$K$2:$K$49,0)) | AC6: 1 | AD6: 1 | AE6: =+INDEX(Equipos!$L$2:$L$49,MATCH(WORLDCUP!AF6,Equipos!$K$2:$K$49,0)) -> 🇿🇦 | AF6: =A6 -> Sudáfrica | AG6: =IF(NOT(OR(ISBLANK(AC6),ISBLANK(AD6))),1,0) -> 1 | AH6: 25 | AI6: =AJ6&$B$4 -> 1A | AJ6: 1 | AK6: =+INDEX(Equipos!$L$2:$L$49,MATCH(WORLDCUP!AL6,Equipos!$K$2:$K$49,0)) -> 🇲🇽 | AL6: =IFERROR(INDEX($BD$6:$BD$53,MATCH(AI6,$BN$6:$BN$53,0)),"") -> México | AM6: =INDEX($BE$6:$BN$53,MATCH($AL6,$BD$6:$BD$53,0),MATCH(AM$5,$BE$5:$BN$5,0)) -> 7 | AN6: =INDEX($BE$6:$BN$53,MATCH($AL6,$BD$6:$BD$53,0),MATCH(AN$5,$BE$5:$BN$5,0)) -> 3 | AO6: =INDEX($BE$6:$BN$53,MATCH($AL6,$BD$6:$BD$53,0),MATCH(AO$5,$BE$5:$BN$5,0)) -> 2 | AP6: =INDEX($BE$6:$BN$53,MATCH($AL6,$BD$6:$BD$53,0),MATCH(AP$5,$BE$5:$BN$5,0)) -> 1 | AQ6: =INDEX($BE$6:$BN$53,MATCH($AL6,$BD$6:$BD$53,0),MATCH(AQ$5,$BE$5:$BN$5,0)) -> 0 | AR6: =INDEX($BE$6:$BN$53,MATCH($AL6,$BD$6:$BD$53,0),MATCH(AR$5,$BE$5:$BN$5,0)) -> 3 | AS6: =INDEX($BE$6:$BN$53,MATCH($AL6,$BD$6:$BD$53,0),MATCH(AS$5,$BE$5:$BN$5,0)) -> 1 | AT6: =INDEX($BE$6:$BN$53,MATCH($AL6,$BD$6:$BD$53,0),MATCH(AT$5,$BE$5:$BN$5,0)) -> 2 | AU6: =INDEX($DJ$6:$DJ$53,MATCH(AI6,$DN$6:$DN$53,0)) -> 1 | AV6: =INDEX($BD$6:$BD$53,MATCH(AI6,$BM$6:$BM$53,0)) -> México | AY6: =+A5 -> México | BC6: =+INDEX(T_Equipos[Grupo],MATCH(WORLDCUP!BD6,T_Equipos[NombreEquipo],0)) -> A | BD6: =+Equipos!B2 -> México | BE6: =+BG6*3+BH6+IF($AZ$3="No",0,INDEX($AZ$6:$AZ$97,MATCH(BD6,$AY$6:$AY$97,0))) -> 7 | BF6: =+BG6+BH6+BI6 -> 3 | BG6: =+COUNTIFS(FGLocal,BD6,Ganador,"Local")+COUNTIFS(FGVisitante,BD6,Ganador,"Visitante") -> 2 | BH6: =+COUNTIFS(FGLocal,BD6,Ganador,"Empate")+COUNTIFS(FGVisitante,BD6,Ganador,"Empate") -> 1 | BI6: =+COUNTIFS(FGVisitante,BD6,Ganador,"Local")+COUNTIFS(FGLocal,BD6,Ganador,"Visitante") -> 0 | BJ6: =+SUMIFS(FG_GolesLocal,FGLocal,BD6,Ganador,"<>"&"Pendiente",FG_GolesLocal,"<>"&"",FG_GolesVisitante,"<>"&"")+SUMIFS(FG_GolesVisitante,FGVisitante,BD6,Ganador,"<>"&"Pendiente",FG_GolesLocal,"<>"&"",FG_GolesVisitante,"<>"&"") -> 3 | BK6: =+SUMIFS(FG_GolesLocal,FGVisitante,BD6,Ganador,"<>"&"Pendiente",FG_GolesLocal,"<>"&"",FG_GolesVisitante,"<>"&"")+SUMIFS(FG_GolesVisitante,FGLocal,BD6,Ganador,"<>"&"Pendiente",FG_GolesLocal,"<>"&"",FG_GolesVisitante,"<>"&"") -> 1 | BL6: =+BJ6-BK6 -> 2 | BM6: =DB6&BC6 -> 1A | BN6: =DF6&BC6 -> 1A | BP6: =+BE6 -> 7 | BQ6: =COUNTIFS($BE$6:$BE$53,">"&BE6,$BC$6:$BC$53,INDEX(T_Equipos[Grupo],MATCH(BD6,T_Equipos[NombreEquipo],0)))+1 -> 1 | BR6: =IF(COUNTIFS($BQ$6:$BQ$53,BQ6,$BC$6:$BC$53,INDEX(T_Equipos[Grupo],MATCH(BD6,T_Equipos[NombreEquipo],0)))=1,"-","P."&BQ6&" ("&COUNTIFS($BQ$6:$BQ$53,BQ6,$BC$6:$BC$53,INDEX(T_Equipos[Grupo],MATCH(BD6,T_Equipos[NombreEquipo],0)))&")") -> - | BS6: =IF($BR6="-","-",COUNTIFS(FGLocal,$BD6,Ganador,"Local",Part1Empate1V,$BR6)+COUNTIFS(FGVisitante,$BD6,Ganador,"Visitante",Part1Empate1L,$BR6)) -> - | BT6: =IF($BR6="-","-",COUNTIFS(FGLocal,$BD6,Ganador,"Empate",Part1Empate1V,$BR6)+COUNTIFS(FGVisitante,$BD6,Ganador,"Empate",Part1Empate1L,$BR6)) -> - | BU6: =IF($BR6="-","-",COUNTIFS(FGLocal,$BD6,Ganador,"Visitante",Part1Empate1V,$BR6)+COUNTIFS(FGVisitante,$BD6,Ganador,"Local",Part1Empate1L,$BR6)) -> - | BV6: =IF($BR6="-","-",BS6*3+BT6) -> - | BW6: =BQ6+COUNTIFS($BR$6:$BR$53,BR6,$BV$6:BV$53,">"&BV6,$BC$6:$BC$53,INDEX(T_Equipos[Grupo],MATCH(BD6,T_Equipos[NombreEquipo],0))) -> 1 | BX6: =IF(COUNTIFS($BW$6:$BW$53,BW6,$BC$6:$BC$53,INDEX(T_Equipos[Grupo],MATCH(BD6,T_Equipos[NombreEquipo],0)))=1,"-","P."&BW6&" ("&COUNTIFS($BW$6:$BW$53,BW6,$BC$6:$BC$53,INDEX(T_Equipos[Grupo],MATCH(BD6,T_Equipos[NombreEquipo],0)))&")") -> - | BY6: =IF($BX6="-","-",SUMIFS(FG_GolesLocal,FGLocal,$BD6,Part1Empate2V,$BX6)+SUMIFS(FG_GolesVisitante,FGVisitante,$BD6,Part1Empate2L,$BX6)) -> - | BZ6: =IF($BX6="-","-",SUMIFS(FG_GolesVisitante,FGLocal,$BD6,Part1Empate2V,$BX6)+SUMIFS(FG_GolesLocal,FGVisitante,$BD6,Part1Empate2L,$BX6)) -> - | CA6: =IF($BX6="-","-",BY6-BZ6) -> - | CB6: =BW6+COUNTIFS($BX$6:$BX$53,BX6,$CA$6:CA$53,">"&CA6,$BC$6:$BC$53,INDEX(T_Equipos[Grupo],MATCH(BD6,T_Equipos[NombreEquipo],0))) -> 1 | CC6: =IF(COUNTIFS($CB$6:$CB$53,CB6,$BC$6:$BC$53,INDEX(T_Equipos[Grupo],MATCH(BD6,T_Equipos[NombreEquipo],0)))=1,"-","P."&CB6&" ("&COUNTIFS($CB$6:$CB$53,CB6,$BC$6:$BC$53,INDEX(T_Equipos[Grupo],MATCH(BD6,T_Equipos[NombreEquipo],0)))&")") -> - | CD6: =IF($CC6="-","-",SUMIFS(FG_GolesLocal,FGLocal,$BD6,Part1Empate3V,$CC6)+SUMIFS(FG_GolesVisitante,FGVisitante,$BD6,Part1Empate3L,$CC6)) -> - | CE6: =CB6+COUNTIFS($CC$6:$CC$53,CC6,$CD$6:CD$53,">"&CD6,$BC$6:$BC$53,INDEX(T_Equipos[Grupo],MATCH(BD6,T_Equipos[NombreEquipo],0))) -> 1 | CF6: =IF(COUNTIFS($CE$6:$CE$53,CE6,$BC$6:$BC$53,INDEX(T_Equipos[Grupo],MATCH(BD6,T_Equipos[NombreEquipo],0)))=1,"-","P."&CE6&" ("&COUNTIFS($CE$6:$CE$53,CE6,$BC$6:$BC$53,INDEX(T_Equipos[Grupo],MATCH(BD6,T_Equipos[NombreEquipo],0)))&")") -> - | CG6: =IF($CF6="-","-",COUNTIFS(FGLocal,$BD6,Ganador,"Local",Part2Empate4V,$CF6)+COUNTIFS(FGVisitante,$BD6,Ganador,"Visitante",Part2Empate4L,$CF6)) -> - | CH6: =IF($CF6="-","-",COUNTIFS(FGLocal,$BD6,Ganador,"Empate",Part2Empate4V,$CF6)+COUNTIFS(FGVisitante,$BD6,Ganador,"Empate",Part2Empate4L,$CF6)) -> - | CI6: =IF($CF6="-","-",COUNTIFS(FGLocal,$BD6,Ganador,"Visitante",Part2Empate4V,$CF6)+COUNTIFS(FGVisitante,$BD6,Ganador,"Local",Part2Empate4L,$CF6)) -> - | CJ6: =IF($CF6="-","-",CG6*3+CH6) -> - | CK6: =CE6+COUNTIFS($CF$6:$CF$53,CF6,$CJ$6:CJ$53,">"&CJ6,$BC$6:$BC$53,INDEX(T_Equipos[Grupo],MATCH(BD6,T_Equipos[NombreEquipo],0))) -> 1 | CL6: =IF(COUNTIFS($CK$6:$CK$53,CK6,$BC$6:$BC$53,INDEX(T_Equipos[Grupo],MATCH(BD6,T_Equipos[NombreEquipo],0)))=1,"-","P."&CK6&" ("&COUNTIFS($CK$6:$CK$53,CK6,$BC$6:$BC$53,INDEX(T_Equipos[Grupo],MATCH(BD6,T_Equipos[NombreEquipo],0)))&")") -> - | CM6: =IF($CL6="-","-",SUMIFS(FG_GolesLocal,FGLocal,$BD6,Part2Empate5V,$CL6)+SUMIFS(FG_GolesVisitante,FGVisitante,$BD6,Part2Empate5L,$CL6)) -> - | CN6: =IF($CL6="-","-",SUMIFS(FG_GolesVisitante,FGLocal,$BD6,Part2Empate5V,$CL6)+SUMIFS(FG_GolesLocal,FGVisitante,$BD6,Part2Empate5L,$CL6)) -> - | CO6: =IF($CL6="-","-",CM6-CN6) -> - | CP6: =CK6+COUNTIFS($CL$6:$CL$53,CL6,$CO$6:CO$53,">"&CO6,$BC$6:$BC$53,INDEX(T_Equipos[Grupo],MATCH(BD6,T_Equipos[NombreEquipo],0))) -> 1 | CQ6: =IF(COUNTIFS($CP$6:$CP$53,CP6,$BC$6:$BC$53,INDEX(T_Equipos[Grupo],MATCH(BD6,T_Equipos[NombreEquipo],0)))=1,"-","P."&CP6&" ("&COUNTIFS($CP$6:$CP$53,CP6,$BC$6:$BC$53,INDEX(T_Equipos[Grupo],MATCH(BD6,T_Equipos[NombreEquipo],0)))&")") -> - | CR6: =IF($CQ6="-","-",SUMIFS(FG_GolesLocal,FGLocal,$BD6,Part2Empate6V,$CQ6)+SUMIFS(FG_GolesVisitante,FGVisitante,$BD6,Part2Empate6L,$CQ6)) -> - | CS6: =CP6+COUNTIFS($CQ$6:$CQ$53,CQ6,$CR$6:CR$53,">"&CR6,$BC$6:$BC$53,INDEX(T_Equipos[Grupo],MATCH(BD6,T_Equipos[NombreEquipo],0))) -> 1 | CT6: =IF(COUNTIFS($CS$6:$CS$53,CS6,$BC$6:$BC$53,INDEX(T_Equipos[Grupo],MATCH(BD6,T_Equipos[NombreEquipo],0)))=1,"-","P."&CS6&" ("&COUNTIFS($CS$6:$CS$53,CS6,$BC$6:$BC$53,INDEX(T_Equipos[Grupo],MATCH(BD6,T_Equipos[NombreEquipo],0)))&")") -> - | CU6: =IF(CT6="-","-",BL6) -> - | CV6: =CS6+COUNTIFS($CT$6:$CT$53,CT6,$CU$6:CU$53,">"&CU6,$BC$6:$BC$53,INDEX(T_Equipos[Grupo],MATCH(BD6,T_Equipos[NombreEquipo],0))) -> 1 | CW6: =IF(COUNTIFS($CV$6:$CV$53,CV6,$BC$6:$BC$53,INDEX(T_Equipos[Grupo],MATCH(BD6,T_Equipos[NombreEquipo],0)))=1,"-","P."&CV6&" ("&COUNTIFS($CV$6:$CV$53,CV6,$BC$6:$BC$53,INDEX(T_Equipos[Grupo],MATCH(BD6,T_Equipos[NombreEquipo],0)))&")") -> - | CX6: =IF(CW6="-","-",BJ6) -> - | CY6: =CV6+COUNTIFS($CW$6:$CW$53,CW6,$CX$6:CX$53,">"&CX6,$BC$6:$BC$53,INDEX(T_Equipos[Grupo],MATCH(BD6,T_Equipos[NombreEquipo],0))) -> 1 | CZ6: =IF(COUNTIFS($CY$6:$CY$53,CY6,$BC$6:$BC$53,INDEX(T_Equipos[Grupo],MATCH(BD6,T_Equipos[NombreEquipo],0)))=1,"-","P."&CY6&" ("&COUNTIFS($CY$6:$CY$53,CY6,$BC$6:$BC$53,INDEX(T_Equipos[Grupo],MATCH(BD6,T_Equipos[NombreEquipo],0)))&")") -> - | DA6: =IF(CZ6="-","-",COUNTIFS(T_Equipos[Rank],"<"&INDEX(T_Equipos[Rank],MATCH(BD6,T_Equipos[NombreEquipo],0)),$BC$6:$BC$53,INDEX(T_Equipos[Grupo],MATCH(BD6,T_Equipos[NombreEquipo],0)))+1) -> - | DB6: =CY6+COUNTIFS($CZ$6:$CZ$53,CZ6,$DA$6:DA$53,"<"&DA6,$BC$6:$BC$53,INDEX(T_Equipos[Grupo],MATCH(BD6,T_Equipos[NombreEquipo],0))) -> 1 | DD6: =IF(OR(INDEX($AW$6:$AW$97,MATCH($BD6,$AV$6:$AV$97,0))="",CZ6="-"),DB6,INDEX($AW$6:$AW$97,MATCH($BD6,$AV$6:$AV$97,0))+DB6/1000) -> 1 | DE6: =IF(CZ6="-","-",COUNTIFS(DD$6:DD$53,"<"&DD6,$BC$6:$BC$53,INDEX(T_Equipos[Grupo],MATCH(BD6,T_Equipos[NombreEquipo],0)))) -> - | DF6: =CY6+COUNTIFS(CZ$6:CZ$53,CZ6,DE$6:DE$53,"<"&DE6,$BC$6:$BC$53,INDEX(T_Equipos[Grupo],MATCH(BD6,T_Equipos[NombreEquipo],0))) -> 1 | DH6: =INDEX($CY$6:$CY$53,MATCH($DO6,$BD$6:$BD$53,0)) -> 1 | DI6: =+SUMIF($BC$6:$BC$53,BC6,$BF$6:$BF$53) -> 12 | DJ6: =IF(OR(DI6=12,$AJ$99=144),COUNTIFS($DH$6:$DH$53,DH6,$BC$6:$BC$53,BC6),1) -> 1 | DK6: =DH6&"."&DJ6 -> 1.1 | DL6: {=OFFSET(Horarios!$P$3,DH6-1,0,DJ6,1)} -> 1 | DN6: 1A | DO6: =INDEX($BD$6:$BD$53,MATCH(DN6,$BM$6:$BM$53,0)) -> México
A7: =+Equipos!B4 -> Corea del Sur | D7: =IF(OR(AC7="",AD7=""),"Pendiente",IF(AC7>AD7,"Local",IF(AC7<AD7,"Visitante","Empate"))) -> Empate | E7: =IF(D7="Pendiente","-",INDEX($BR$6:$BR$53,MATCH($AA7,$BD$6:$BD$53,0))) -> - | F7: =IF(D7="Pendiente","-",INDEX($BR$6:$BR$53,MATCH($AF7,$BD$6:$BD$53,0))) -> P.3 (2) | H7: =IF(D7="Pendiente","-",INDEX($BX$6:$BX$53,MATCH($AA7,$BD$6:$BD$53,0))) -> - | I7: =IF(D7="Pendiente","-",INDEX($BX$6:$BX$53,MATCH($AF7,$BD$6:$BD$53,0))) -> P.3 (2) | K7: =IF(D7="Pendiente","-",INDEX($CC$6:$CC$53,MATCH($AA7,$BD$6:$BD$53,0))) -> - | L7: =IF(D7="Pendiente","-",INDEX($CC$6:$CC$53,MATCH($AF7,$BD$6:$BD$53,0))) -> P.3 (2) | N7: =IF(D7="Pendiente","-",INDEX($CF$6:$CF$53,MATCH($AA7,$BD$6:$BD$53,0))) -> - | O7: =IF(D7="Pendiente","-",INDEX($CF$6:$CF$53,MATCH($AF7,$BD$6:$BD$53,0))) -> P.3 (2) | Q7: =IF(D7="Pendiente","-",INDEX($CL$6:$CL$53,MATCH($AA7,$BD$6:$BD$53,0))) -> - | R7: =IF(D7="Pendiente","-",INDEX($CL$6:$CL$53,MATCH($AF7,$BD$6:$BD$53,0))) -> P.3 (2) | T7: =IF(D7="Pendiente","-",INDEX($CQ$6:$CQ$53,MATCH($AA7,$BD$6:$BD$53,0))) -> - | U7: =IF(D7="Pendiente","-",INDEX($CQ$6:$CQ$53,MATCH($AF7,$BD$6:$BD$53,0))) -> P.3 (2) | X7: =Horarios!C7 -> 46192.125 | Y7: =Horarios!C7 -> 46192.125 | Z7: =$Z$6 -> J2 | AA7: =A5 -> México | AB7: =+INDEX(Equipos!$L$2:$L$49,MATCH(WORLDCUP!AA7,Equipos!$K$2:$K$49,0)) -> 🇲🇽 | AC7: 0 | AD7: 0 | AE7: =+INDEX(Equipos!$L$2:$L$49,MATCH(WORLDCUP!AF7,Equipos!$K$2:$K$49,0)) -> 🇰🇷 | AF7: =A7 -> Corea del Sur | AG7: =IF(NOT(OR(ISBLANK(AC7),ISBLANK(AD7))),1,0) -> 1 | AH7: 28 | AI7: =AJ7&$B$4 -> 2A | AJ7: 2 | AK7: =+INDEX(Equipos!$L$2:$L$49,MATCH(WORLDCUP!AL7,Equipos!$K$2:$K$49,0)) -> 🇿🇦 | AL7: =IFERROR(INDEX($BD$6:$BD$53,MATCH(AI7,$BN$6:$BN$53,0)),"") -> Sudáfrica | AM7: =INDEX($BE$6:$BN$53,MATCH($AL7,$BD$6:$BD$53,0),MATCH(AM$5,$BE$5:$BN$5,0)) -> 4 | AN7: =INDEX($BE$6:$BN$53,MATCH($AL7,$BD$6:$BD$53,0),MATCH(AN$5,$BE$5:$BN$5,0)) -> 3 | AO7: =INDEX($BE$6:$BN$53,MATCH($AL7,$BD$6:$BD$53,0),MATCH(AO$5,$BE$5:$BN$5,0)) -> 1 | AP7: =INDEX($BE$6:$BN$53,MATCH($AL7,$BD$6:$BD$53,0),MATCH(AP$5,$BE$5:$BN$5,0)) -> 1 | AQ7: =INDEX($BE$6:$BN$53,MATCH($AL7,$BD$6:$BD$53,0),MATCH(AQ$5,$BE$5:$BN$5,0)) -> 1 | AR7: =INDEX($BE$6:$BN$53,MATCH($AL7,$BD$6:$BD$53,0),MATCH(AR$5,$BE$5:$BN$5,0)) -> 3 | AS7: =INDEX($BE$6:$BN$53,MATCH($AL7,$BD$6:$BD$53,0),MATCH(AS$5,$BE$5:$BN$5,0)) -> 3 | AT7: =INDEX($BE$6:$BN$53,MATCH($AL7,$BD$6:$BD$53,0),MATCH(AT$5,$BE$5:$BN$5,0)) -> 0 | AU7: =INDEX($DJ$6:$DJ$53,MATCH(AI7,$DN$6:$DN$53,0)) -> 1 | AV7: =INDEX($BD$6:$BD$53,MATCH(AI7,$BM$6:$BM$53,0)) -> Sudáfrica | AY7: =+A6 -> Sudáfrica | BC7: =+INDEX(T_Equipos[Grupo],MATCH(WORLDCUP!BD7,T_Equipos[NombreEquipo],0)) -> A | BD7: =+Equipos!B3 -> Sudáfrica | BE7: =+BG7*3+BH7+IF($AZ$3="No",0,INDEX($AZ$6:$AZ$97,MATCH(BD7,$AY$6:$AY$97,0))) -> 4 | BF7: =+BG7+BH7+BI7 -> 3 | BG7: =+COUNTIFS(FGLocal,BD7,Ganador,"Local")+COUNTIFS(FGVisitante,BD7,Ganador,"Visitante") -> 1 | BH7: =+COUNTIFS(FGLocal,BD7,Ganador,"Empate")+COUNTIFS(FGVisitante,BD7,Ganador,"Empate") -> 1 | BI7: =+COUNTIFS(FGVisitante,BD7,Ganador,"Local")+COUNTIFS(FGLocal,BD7,Ganador,"Visitante") -> 1 | BJ7: =+SUMIFS(FG_GolesLocal,FGLocal,BD7,Ganador,"<>"&"Pendiente",FG_GolesLocal,"<>"&"",FG_GolesVisitante,"<>"&"")+SUMIFS(FG_GolesVisitante,FGVisitante,BD7,Ganador,"<>"&"Pendiente",FG_GolesLocal,"<>"&"",FG_GolesVisitante,"<>"&"") -> 3 | BK7: =+SUMIFS(FG_GolesLocal,FGVisitante,BD7,Ganador,"<>"&"Pendiente",FG_GolesLocal,"<>"&"",FG_GolesVisitante,"<>"&"")+SUMIFS(FG_GolesVisitante,FGLocal,BD7,Ganador,"<>"&"Pendiente",FG_GolesLocal,"<>"&"",FG_GolesVisitante,"<>"&"") -> 3 | BL7: =+BJ7-BK7 -> 0 | BM7: =DB7&BC7 -> 2A | BN7: =DF7&BC7 -> 2A | BP7: =+BE7 -> 4 | BQ7: =COUNTIFS($BE$6:$BE$53,">"&BE7,$BC$6:$BC$53,INDEX(T_Equipos[Grupo],MATCH(BD7,T_Equipos[NombreEquipo],0)))+1 -> 2 | BR7: =IF(COUNTIFS($BQ$6:$BQ$53,BQ7,$BC$6:$BC$53,INDEX(T_Equipos[Grupo],MATCH(BD7,T_Equipos[NombreEquipo],0)))=1,"-","P."&BQ7&" ("&COUNTIFS($BQ$6:$BQ$53,BQ7,$BC$6:$BC$53,INDEX(T_Equipos[Grupo],MATCH(BD7,T_Equipos[NombreEquipo],0)))&")") -> - | BS7: =IF($BR7="-","-",COUNTIFS(FGLocal,$BD7,Ganador,"Local",Part1Empate1V,$BR7)+COUNTIFS(FGVisitante,$BD7,Ganador,"Visitante",Part1Empate1L,$BR7)) -> - | BT7: =IF($BR7="-","-",COUNTIFS(FGLocal,$BD7,Ganador,"Empate",Part1Empate1V,$BR7)+COUNTIFS(FGVisitante,$BD7,Ganador,"Empate",Part1Empate1L,$BR7)) -> - | BU7: =IF($BR7="-","-",COUNTIFS(FGLocal,$BD7,Ganador,"Visitante",Part1Empate1V,$BR7)+COUNTIFS(FGVisitante,$BD7,Ganador,"Local",Part1Empate1L,$BR7)) -> - | BV7: =IF($BR7="-","-",BS7*3+BT7) -> - | BW7: =BQ7+COUNTIFS($BR$6:$BR$53,BR7,$BV$6:BV$53,">"&BV7,$BC$6:$BC$53,INDEX(T_Equipos[Grupo],MATCH(BD7,T_Equipos[NombreEquipo],0))) -> 2 | BX7: =IF(COUNTIFS($BW$6:$BW$53,BW7,$BC$6:$BC$53,INDEX(T_Equipos[Grupo],MATCH(BD7,T_Equipos[NombreEquipo],0)))=1,"-","P."&BW7&" ("&COUNTIFS($BW$6:$BW$53,BW7,$BC$6:$BC$53,INDEX(T_Equipos[Grupo],MATCH(BD7,T_Equipos[NombreEquipo],0)))&")") -> - | BY7: =IF($BX7="-","-",SUMIFS(FG_GolesLocal,FGLocal,$BD7,Part1Empate2V,$BX7)+SUMIFS(FG_GolesVisitante,FGVisitante,$BD7,Part1Empate2L,$BX7)) -> - | BZ7: =IF($BX7="-","-",SUMIFS(FG_GolesVisitante,FGLocal,$BD7,Part1Empate2V,$BX7)+SUMIFS(FG_GolesLocal,FGVisitante,$BD7,Part1Empate2L,$BX7)) -> - | CA7: =IF($BX7="-","-",BY7-BZ7) -> - | CB7: =BW7+COUNTIFS($BX$6:$BX$53,BX7,$CA$6:CA$53,">"&CA7,$BC$6:$BC$53,INDEX(T_Equipos[Grupo],MATCH(BD7,T_Equipos[NombreEquipo],0))) -> 2 | CC7: =IF(COUNTIFS($CB$6:$CB$53,CB7,$BC$6:$BC$53,INDEX(T_Equipos[Grupo],MATCH(BD7,T_Equipos[NombreEquipo],0)))=1,"-","P."&CB7&" ("&COUNTIFS($CB$6:$CB$53,CB7,$BC$6:$BC$53,INDEX(T_Equipos[Grupo],MATCH(BD7,T_Equipos[NombreEquipo],0)))&")") -> - | CD7: =IF($CC7="-","-",SUMIFS(FG_GolesLocal,FGLocal,$BD7,Part1Empate3V,$CC7)+SUMIFS(FG_GolesVisitante,FGVisitante,$BD7,Part1Empate3L,$CC7)) -> - | CE7: =CB7+COUNTIFS($CC$6:$CC$53,CC7,$CD$6:CD$53,">"&CD7,$BC$6:$BC$53,INDEX(T_Equipos[Grupo],MATCH(BD7,T_Equipos[NombreEquipo],0))) -> 2 | CF7: =IF(COUNTIFS($CE$6:$CE$53,CE7,$BC$6:$BC$53,INDEX(T_Equipos[Grupo],MATCH(BD7,T_Equipos[NombreEquipo],0)))=1,"-","P."&CE7&" ("&COUNTIFS($CE$6:$CE$53,CE7,$BC$6:$BC$53,INDEX(T_Equipos[Grupo],MATCH(BD7,T_Equipos[NombreEquipo],0)))&")") -> - | CG7: =IF($CF7="-","-",COUNTIFS(FGLocal,$BD7,Ganador,"Local",Part2Empate4V,$CF7)+COUNTIFS(FGVisitante,$BD7,Ganador,"Visitante",Part2Empate4L,$CF7)) -> - | CH7: =IF($CF7="-","-",COUNTIFS(FGLocal,$BD7,Ganador,"Empate",Part2Empate4V,$CF7)+COUNTIFS(FGVisitante,$BD7,Ganador,"Empate",Part2Empate4L,$CF7)) -> - | CI7: =IF($CF7="-","-",COUNTIFS(FGLocal,$BD7,Ganador,"Visitante",Part2Empate4V,$CF7)+COUNTIFS(FGVisitante,$BD7,Ganador,"Local",Part2Empate4L,$CF7)) -> - | CJ7: =IF($CF7="-","-",CG7*3+CH7) -> - | CK7: =CE7+COUNTIFS($CF$6:$CF$53,CF7,$CJ$6:CJ$53,">"&CJ7,$BC$6:$BC$53,INDEX(T_Equipos[Grupo],MATCH(BD7,T_Equipos[NombreEquipo],0))) -> 2 | CL7: =IF(COUNTIFS($CK$6:$CK$53,CK7,$BC$6:$BC$53,INDEX(T_Equipos[Grupo],MATCH(BD7,T_Equipos[NombreEquipo],0)))=1,"-","P."&CK7&" ("&COUNTIFS($CK$6:$CK$53,CK7,$BC$6:$BC$53,INDEX(T_Equipos[Grupo],MATCH(BD7,T_Equipos[NombreEquipo],0)))&")") -> - | CM7: =IF($CL7="-","-",SUMIFS(FG_GolesLocal,FGLocal,$BD7,Part2Empate5V,$CL7)+SUMIFS(FG_GolesVisitante,FGVisitante,$BD7,Part2Empate5L,$CL7)) -> - | CN7: =IF($CL7="-","-",SUMIFS(FG_GolesVisitante,FGLocal,$BD7,Part2Empate5V,$CL7)+SUMIFS(FG_GolesLocal,FGVisitante,$BD7,Part2Empate5L,$CL7)) -> - | CO7: =IF($CL7="-","-",CM7-CN7) -> - | CP7: =CK7+COUNTIFS($CL$6:$CL$53,CL7,$CO$6:CO$53,">"&CO7,$BC$6:$BC$53,INDEX(T_Equipos[Grupo],MATCH(BD7,T_Equipos[NombreEquipo],0))) -> 2 | CQ7: =IF(COUNTIFS($CP$6:$CP$53,CP7,$BC$6:$BC$53,INDEX(T_Equipos[Grupo],MATCH(BD7,T_Equipos[NombreEquipo],0)))=1,"-","P."&CP7&" ("&COUNTIFS($CP$6:$CP$53,CP7,$BC$6:$BC$53,INDEX(T_Equipos[Grupo],MATCH(BD7,T_Equipos[NombreEquipo],0)))&")") -> - | CR7: =IF($CQ7="-","-",SUMIFS(FG_GolesLocal,FGLocal,$BD7,Part2Empate6V,$CQ7)+SUMIFS(FG_GolesVisitante,FGVisitante,$BD7,Part2Empate6L,$CQ7)) -> - | CS7: =CP7+COUNTIFS($CQ$6:$CQ$53,CQ7,$CR$6:CR$53,">"&CR7,$BC$6:$BC$53,INDEX(T_Equipos[Grupo],MATCH(BD7,T_Equipos[NombreEquipo],0))) -> 2 | CT7: =IF(COUNTIFS($CS$6:$CS$53,CS7,$BC$6:$BC$53,INDEX(T_Equipos[Grupo],MATCH(BD7,T_Equipos[NombreEquipo],0)))=1,"-","P."&CS7&" ("&COUNTIFS($CS$6:$CS$53,CS7,$BC$6:$BC$53,INDEX(T_Equipos[Grupo],MATCH(BD7,T_Equipos[NombreEquipo],0)))&")") -> - | CU7: =IF(CT7="-","-",BL7) -> - | CV7: =CS7+COUNTIFS($CT$6:$CT$53,CT7,$CU$6:CU$53,">"&CU7,$BC$6:$BC$53,INDEX(T_Equipos[Grupo],MATCH(BD7,T_Equipos[NombreEquipo],0))) -> 2 | CW7: =IF(COUNTIFS($CV$6:$CV$53,CV7,$BC$6:$BC$53,INDEX(T_Equipos[Grupo],MATCH(BD7,T_Equipos[NombreEquipo],0)))=1,"-","P."&CV7&" ("&COUNTIFS($CV$6:$CV$53,CV7,$BC$6:$BC$53,INDEX(T_Equipos[Grupo],MATCH(BD7,T_Equipos[NombreEquipo],0)))&")") -> - | CX7: =IF(CW7="-","-",BJ7) -> - | CY7: =CV7+COUNTIFS($CW$6:$CW$53,CW7,$CX$6:CX$53,">"&CX7,$BC$6:$BC$53,INDEX(T_Equipos[Grupo],MATCH(BD7,T_Equipos[NombreEquipo],0))) -> 2 | CZ7: =IF(COUNTIFS($CY$6:$CY$53,CY7,$BC$6:$BC$53,INDEX(T_Equipos[Grupo],MATCH(BD7,T_Equipos[NombreEquipo],0)))=1,"-","P."&CY7&" ("&COUNTIFS($CY$6:$CY$53,CY7,$BC$6:$BC$53,INDEX(T_Equipos[Grupo],MATCH(BD7,T_Equipos[NombreEquipo],0)))&")") -> - | DA7: =IF(CZ7="-","-",COUNTIFS(T_Equipos[Rank],"<"&INDEX(T_Equipos[Rank],MATCH(BD7,T_Equipos[NombreEquipo],0)),$BC$6:$BC$53,INDEX(T_Equipos[Grupo],MATCH(BD7,T_Equipos[NombreEquipo],0)))+1) -> - | DB7: =CY7+COUNTIFS($CZ$6:$CZ$53,CZ7,$DA$6:DA$53,"<"&DA7,$BC$6:$BC$53,INDEX(T_Equipos[Grupo],MATCH(BD7,T_Equipos[NombreEquipo],0))) -> 2 | DD7: =IF(OR(INDEX($AW$6:$AW$97,MATCH($BD7,$AV$6:$AV$97,0))="",CZ7="-"),DB7,INDEX($AW$6:$AW$97,MATCH($BD7,$AV$6:$AV$97,0))+DB7/1000) -> 2 | DE7: =IF(CZ7="-","-",COUNTIFS(DD$6:DD$53,"<"&DD7,$BC$6:$BC$53,INDEX(T_Equipos[Grupo],MATCH(BD7,T_Equipos[NombreEquipo],0)))) -> - | DF7: =CY7+COUNTIFS(CZ$6:CZ$53,CZ7,DE$6:DE$53,"<"&DE7,$BC$6:$BC$53,INDEX(T_Equipos[Grupo],MATCH(BD7,T_Equipos[NombreEquipo],0))) -> 2 | DH7: =INDEX($CY$6:$CY$53,MATCH($DO7,$BD$6:$BD$53,0)) -> 2 | DI7: =+SUMIF($BC$6:$BC$53,BC7,$BF$6:$BF$53) -> 12 | DJ7: =IF(OR(DI7=12,$AJ$99=144),COUNTIFS($DH$6:$DH$53,DH7,$BC$6:$BC$53,BC7),1) -> 1 | DK7: =DH7&"."&DJ7 -> 2.1 | DL7: {=OFFSET(Horarios!$P$3,DH7-1,0,DJ7,1)} -> 2 | DN7: 2A | DO7: =INDEX($BD$6:$BD$53,MATCH(DN7,$BM$6:$BM$53,0)) -> Sudáfrica
A8: =+Equipos!B5 -> PO D: DEN/MKD/CZE/IRL | D8: =IF(OR(AC8="",AD8=""),"Pendiente",IF(AC8>AD8,"Local",IF(AC8<AD8,"Visitante","Empate"))) -> Visitante | E8: =IF(D8="Pendiente","-",INDEX($BR$6:$BR$53,MATCH($AA8,$BD$6:$BD$53,0))) -> P.3 (2) | F8: =IF(D8="Pendiente","-",INDEX($BR$6:$BR$53,MATCH($AF8,$BD$6:$BD$53,0))) -> - | H8: =IF(D8="Pendiente","-",INDEX($BX$6:$BX$53,MATCH($AA8,$BD$6:$BD$53,0))) -> P.3 (2) | I8: =IF(D8="Pendiente","-",INDEX($BX$6:$BX$53,MATCH($AF8,$BD$6:$BD$53,0))) -> - | K8: =IF(D8="Pendiente","-",INDEX($CC$6:$CC$53,MATCH($AA8,$BD$6:$BD$53,0))) -> P.3 (2) | L8: =IF(D8="Pendiente","-",INDEX($CC$6:$CC$53,MATCH($AF8,$BD$6:$BD$53,0))) -> - | N8: =IF(D8="Pendiente","-",INDEX($CF$6:$CF$53,MATCH($AA8,$BD$6:$BD$53,0))) -> P.3 (2) | O8: =IF(D8="Pendiente","-",INDEX($CF$6:$CF$53,MATCH($AF8,$BD$6:$BD$53,0))) -> - | Q8: =IF(D8="Pendiente","-",INDEX($CL$6:$CL$53,MATCH($AA8,$BD$6:$BD$53,0))) -> P.3 (2) | R8: =IF(D8="Pendiente","-",INDEX($CL$6:$CL$53,MATCH($AF8,$BD$6:$BD$53,0))) -> - | T8: =IF(D8="Pendiente","-",INDEX($CQ$6:$CQ$53,MATCH($AA8,$BD$6:$BD$53,0))) -> P.3 (2) | U8: =IF(D8="Pendiente","-",INDEX($CQ$6:$CQ$53,MATCH($AF8,$BD$6:$BD$53,0))) -> - | X8: =Horarios!C8 -> 46198.125 | Y8: =Horarios!C8 -> 46198.125 | Z8: =Idiomas!D63 -> J3 | AA8: =A8 -> PO D: DEN/MKD/CZE/IRL | AB8: =+INDEX(Equipos!$L$2:$L$49,MATCH(WORLDCUP!AA8,Equipos!$K$2:$K$49,0)) | AC8: 0 | AD8: 1 | AE8: =+INDEX(Equipos!$L$2:$L$49,MATCH(WORLDCUP!AF8,Equipos!$K$2:$K$49,0)) -> 🇲🇽 | AF8: =A5 -> México | AG8: =IF(NOT(OR(ISBLANK(AC8),ISBLANK(AD8))),1,0) -> 1 | AH8: 53 | AI8: =AJ8&$B$4 -> 3A | AJ8: 3 | AK8: =+INDEX(Equipos!$L$2:$L$49,MATCH(WORLDCUP!AL8,Equipos!$K$2:$K$49,0)) | AL8: =IFERROR(INDEX($BD$6:$BD$53,MATCH(AI8,$BN$6:$BN$53,0)),"") -> PO D: DEN/MKD/CZE/IRL | AM8: =INDEX($BE$6:$BN$53,MATCH($AL8,$BD$6:$BD$53,0),MATCH(AM$5,$BE$5:$BN$5,0)) -> 2 | AN8: =INDEX($BE$6:$BN$53,MATCH($AL8,$BD$6:$BD$53,0),MATCH(AN$5,$BE$5:$BN$5,0)) -> 3 | AO8: =INDEX($BE$6:$BN$53,MATCH($AL8,$BD$6:$BD$53,0),MATCH(AO$5,$BE$5:$BN$5,0)) -> 0 | AP8: =INDEX($BE$6:$BN$53,MATCH($AL8,$BD$6:$BD$53,0),MATCH(AP$5,$BE$5:$BN$5,0)) -> 2 | AQ8: =INDEX($BE$6:$BN$53,MATCH($AL8,$BD$6:$BD$53,0),MATCH(AQ$5,$BE$5:$BN$5,0)) -> 1 | AR8: =INDEX($BE$6:$BN$53,MATCH($AL8,$BD$6:$BD$53,0),MATCH(AR$5,$BE$5:$BN$5,0)) -> 2 | AS8: =INDEX($BE$6:$BN$53,MATCH($AL8,$BD$6:$BD$53,0),MATCH(AS$5,$BE$5:$BN$5,0)) -> 3 | AT8: =INDEX($BE$6:$BN$53,MATCH($AL8,$BD$6:$BD$53,0),MATCH(AT$5,$BE$5:$BN$5,0)) -> -1 | AU8: =INDEX($DJ$6:$DJ$53,MATCH(AI8,$DN$6:$DN$53,0)) -> 1 | AV8: =INDEX($BD$6:$BD$53,MATCH(AI8,$BM$6:$BM$53,0)) -> PO D: DEN/MKD/CZE/IRL | AY8: =+A7 -> Corea del Sur | BC8: =+INDEX(T_Equipos[Grupo],MATCH(WORLDCUP!BD8,T_Equipos[NombreEquipo],0)) -> A | BD8: =+Equipos!B4 -> Corea del Sur | BE8: =+BG8*3+BH8+IF($AZ$3="No",0,INDEX($AZ$6:$AZ$97,MATCH(BD8,$AY$6:$AY$97,0))) -> 2 | BF8: =+BG8+BH8+BI8 -> 3 | BG8: =+COUNTIFS(FGLocal,BD8,Ganador,"Local")+COUNTIFS(FGVisitante,BD8,Ganador,"Visitante") -> 0 | BH8: =+COUNTIFS(FGLocal,BD8,Ganador,"Empate")+COUNTIFS(FGVisitante,BD8,Ganador,"Empate") -> 2 | BI8: =+COUNTIFS(FGVisitante,BD8,Ganador,"Local")+COUNTIFS(FGLocal,BD8,Ganador,"Visitante") -> 1 | BJ8: =+SUMIFS(FG_GolesLocal,FGLocal,BD8,Ganador,"<>"&"Pendiente",FG_GolesLocal,"<>"&"",FG_GolesVisitante,"<>"&"")+SUMIFS(FG_GolesVisitante,FGVisitante,BD8,Ganador,"<>"&"Pendiente",FG_GolesLocal,"<>"&"",FG_GolesVisitante,"<>"&"") -> 1 | BK8: =+SUMIFS(FG_GolesLocal,FGVisitante,BD8,Ganador,"<>"&"Pendiente",FG_GolesLocal,"<>"&"",FG_GolesVisitante,"<>"&"")+SUMIFS(FG_GolesVisitante,FGLocal,BD8,Ganador,"<>"&"Pendiente",FG_GolesLocal,"<>"&"",FG_GolesVisitante,"<>"&"") -> 2 | BL8: =+BJ8-BK8 -> -1 | BM8: =DB8&BC8 -> 4A | BN8: =DF8&BC8 -> 4A | BP8: =+BE8 -> 2 | BQ8: =COUNTIFS($BE$6:$BE$53,">"&BE8,$BC$6:$BC$53,INDEX(T_Equipos[Grupo],MATCH(BD8,T_Equipos[NombreEquipo],0)))+1 -> 3 | BR8: =IF(COUNTIFS($BQ$6:$BQ$53,BQ8,$BC$6:$BC$53,INDEX(T_Equipos[Grupo],MATCH(BD8,T_Equipos[NombreEquipo],0)))=1,"-","P."&BQ8&" ("&COUNTIFS($BQ$6:$BQ$53,BQ8,$BC$6:$BC$53,INDEX(T_Equipos[Grupo],MATCH(BD8,T_Equipos[NombreEquipo],0)))&")") -> P.3 (2) | BS8: =IF($BR8="-","-",COUNTIFS(FGLocal,$BD8,Ganador,"Local",Part1Empate1V,$BR8)+COUNTIFS(FGVisitante,$BD8,Ganador,"Visitante",Part1Empate1L,$BR8)) -> 0 | BT8: =IF($BR8="-","-",COUNTIFS(FGLocal,$BD8,Ganador,"Empate",Part1Empate1V,$BR8)+COUNTIFS(FGVisitante,$BD8,Ganador,"Empate",Part1Empate1L,$BR8)) -> 1 | BU8: =IF($BR8="-","-",COUNTIFS(FGLocal,$BD8,Ganador,"Visitante",Part1Empate1V,$BR8)+COUNTIFS(FGVisitante,$BD8,Ganador,"Local",Part1Empate1L,$BR8)) -> 0 | BV8: =IF($BR8="-","-",BS8*3+BT8) -> 1 | BW8: =BQ8+COUNTIFS($BR$6:$BR$53,BR8,$BV$6:BV$53,">"&BV8,$BC$6:$BC$53,INDEX(T_Equipos[Grupo],MATCH(BD8,T_Equipos[NombreEquipo],0))) -> 3 | BX8: =IF(COUNTIFS($BW$6:$BW$53,BW8,$BC$6:$BC$53,INDEX(T_Equipos[Grupo],MATCH(BD8,T_Equipos[NombreEquipo],0)))=1,"-","P."&BW8&" ("&COUNTIFS($BW$6:$BW$53,BW8,$BC$6:$BC$53,INDEX(T_Equipos[Grupo],MATCH(BD8,T_Equipos[NombreEquipo],0)))&")") -> P.3 (2) | BY8: =IF($BX8="-","-",SUMIFS(FG_GolesLocal,FGLocal,$BD8,Part1Empate2V,$BX8)+SUMIFS(FG_GolesVisitante,FGVisitante,$BD8,Part1Empate2L,$BX8)) -> 1 | BZ8: =IF($BX8="-","-",SUMIFS(FG_GolesVisitante,FGLocal,$BD8,Part1Empate2V,$BX8)+SUMIFS(FG_GolesLocal,FGVisitante,$BD8,Part1Empate2L,$BX8)) -> 1 | CA8: =IF($BX8="-","-",BY8-BZ8) -> 0 | CB8: =BW8+COUNTIFS($BX$6:$BX$53,BX8,$CA$6:CA$53,">"&CA8,$BC$6:$BC$53,INDEX(T_Equipos[Grupo],MATCH(BD8,T_Equipos[NombreEquipo],0))) -> 3 | CC8: =IF(COUNTIFS($CB$6:$CB$53,CB8,$BC$6:$BC$53,INDEX(T_Equipos[Grupo],MATCH(BD8,T_Equipos[NombreEquipo],0)))=1,"-","P."&CB8&" ("&COUNTIFS($CB$6:$CB$53,CB8,$BC$6:$BC$53,INDEX(T_Equipos[Grupo],MATCH(BD8,T_Equipos[NombreEquipo],0)))&")") -> P.3 (2) | CD8: =IF($CC8="-","-",SUMIFS(FG_GolesLocal,FGLocal,$BD8,Part1Empate3V,$CC8)+SUMIFS(FG_GolesVisitante,FGVisitante,$BD8,Part1Empate3L,$CC8)) -> 1 | CE8: =CB8+COUNTIFS($CC$6:$CC$53,CC8,$CD$6:CD$53,">"&CD8,$BC$6:$BC$53,INDEX(T_Equipos[Grupo],MATCH(BD8,T_Equipos[NombreEquipo],0))) -> 3 | CF8: =IF(COUNTIFS($CE$6:$CE$53,CE8,$BC$6:$BC$53,INDEX(T_Equipos[Grupo],MATCH(BD8,T_Equipos[NombreEquipo],0)))=1,"-","P."&CE8&" ("&COUNTIFS($CE$6:$CE$53,CE8,$BC$6:$BC$53,INDEX(T_Equipos[Grupo],MATCH(BD8,T_Equipos[NombreEquipo],0)))&")") -> P.3 (2) | CG8: =IF($CF8="-","-",COUNTIFS(FGLocal,$BD8,Ganador,"Local",Part2Empate4V,$CF8)+COUNTIFS(FGVisitante,$BD8,Ganador,"Visitante",Part2Empate4L,$CF8)) -> 0 | CH8: =IF($CF8="-","-",COUNTIFS(FGLocal,$BD8,Ganador,"Empate",Part2Empate4V,$CF8)+COUNTIFS(FGVisitante,$BD8,Ganador,"Empate",Part2Empate4L,$CF8)) -> 1 | CI8: =IF($CF8="-","-",COUNTIFS(FGLocal,$BD8,Ganador,"Visitante",Part2Empate4V,$CF8)+COUNTIFS(FGVisitante,$BD8,Ganador,"Local",Part2Empate4L,$CF8)) -> 0 | CJ8: =IF($CF8="-","-",CG8*3+CH8) -> 1 | CK8: =CE8+COUNTIFS($CF$6:$CF$53,CF8,$CJ$6:CJ$53,">"&CJ8,$BC$6:$BC$53,INDEX(T_Equipos[Grupo],MATCH(BD8,T_Equipos[NombreEquipo],0))) -> 3 | CL8: =IF(COUNTIFS($CK$6:$CK$53,CK8,$BC$6:$BC$53,INDEX(T_Equipos[Grupo],MATCH(BD8,T_Equipos[NombreEquipo],0)))=1,"-","P."&CK8&" ("&COUNTIFS($CK$6:$CK$53,CK8,$BC$6:$BC$53,INDEX(T_Equipos[Grupo],MATCH(BD8,T_Equipos[NombreEquipo],0)))&")") -> P.3 (2) | CM8: =IF($CL8="-","-",SUMIFS(FG_GolesLocal,FGLocal,$BD8,Part2Empate5V,$CL8)+SUMIFS(FG_GolesVisitante,FGVisitante,$BD8,Part2Empate5L,$CL8)) -> 1 | CN8: =IF($CL8="-","-",SUMIFS(FG_GolesVisitante,FGLocal,$BD8,Part2Empate5V,$CL8)+SUMIFS(FG_GolesLocal,FGVisitante,$BD8,Part2Empate5L,$CL8)) -> 1 | CO8: =IF($CL8="-","-",CM8-CN8) -> 0 | CP8: =CK8+COUNTIFS($CL$6:$CL$53,CL8,$CO$6:CO$53,">"&CO8,$BC$6:$BC$53,INDEX(T_Equipos[Grupo],MATCH(BD8,T_Equipos[NombreEquipo],0))) -> 3 | CQ8: =IF(COUNTIFS($CP$6:$CP$53,CP8,$BC$6:$BC$53,INDEX(T_Equipos[Grupo],MATCH(BD8,T_Equipos[NombreEquipo],0)))=1,"-","P."&CP8&" ("&COUNTIFS($CP$6:$CP$53,CP8,$BC$6:$BC$53,INDEX(T_Equipos[Grupo],MATCH(BD8,T_Equipos[NombreEquipo],0)))&")") -> P.3 (2) | CR8: =IF($CQ8="-","-",SUMIFS(FG_GolesLocal,FGLocal,$BD8,Part2Empate6V,$CQ8)+SUMIFS(FG_GolesVisitante,FGVisitante,$BD8,Part2Empate6L,$CQ8)) -> 1 | CS8: =CP8+COUNTIFS($CQ$6:$CQ$53,CQ8,$CR$6:CR$53,">"&CR8,$BC$6:$BC$53,INDEX(T_Equipos[Grupo],MATCH(BD8,T_Equipos[NombreEquipo],0))) -> 3 | CT8: =IF(COUNTIFS($CS$6:$CS$53,CS8,$BC$6:$BC$53,INDEX(T_Equipos[Grupo],MATCH(BD8,T_Equipos[NombreEquipo],0)))=1,"-","P."&CS8&" ("&COUNTIFS($CS$6:$CS$53,CS8,$BC$6:$BC$53,INDEX(T_Equipos[Grupo],MATCH(BD8,T_Equipos[NombreEquipo],0)))&")") -> P.3 (2) | CU8: =IF(CT8="-","-",BL8) -> -1 | CV8: =CS8+COUNTIFS($CT$6:$CT$53,CT8,$CU$6:CU$53,">"&CU8,$BC$6:$BC$53,INDEX(T_Equipos[Grupo],MATCH(BD8,T_Equipos[NombreEquipo],0))) -> 3 | CW8: =IF(COUNTIFS($CV$6:$CV$53,CV8,$BC$6:$BC$53,INDEX(T_Equipos[Grupo],MATCH(BD8,T_Equipos[NombreEquipo],0)))=1,"-","P."&CV8&" ("&COUNTIFS($CV$6:$CV$53,CV8,$BC$6:$BC$53,INDEX(T_Equipos[Grupo],MATCH(BD8,T_Equipos[NombreEquipo],0)))&")") -> P.3 (2) | CX8: =IF(CW8="-","-",BJ8) -> 1 | CY8: =CV8+COUNTIFS($CW$6:$CW$53,CW8,$CX$6:CX$53,">"&CX8,$BC$6:$BC$53,INDEX(T_Equipos[Grupo],MATCH(BD8,T_Equipos[NombreEquipo],0))) -> 4 | CZ8: =IF(COUNTIFS($CY$6:$CY$53,CY8,$BC$6:$BC$53,INDEX(T_Equipos[Grupo],MATCH(BD8,T_Equipos[NombreEquipo],0)))=1,"-","P."&CY8&" ("&COUNTIFS($CY$6:$CY$53,CY8,$BC$6:$BC$53,INDEX(T_Equipos[Grupo],MATCH(BD8,T_Equipos[NombreEquipo],0)))&")") -> - | DA8: =IF(CZ8="-","-",COUNTIFS(T_Equipos[Rank],"<"&INDEX(T_Equipos[Rank],MATCH(BD8,T_Equipos[NombreEquipo],0)),$BC$6:$BC$53,INDEX(T_Equipos[Grupo],MATCH(BD8,T_Equipos[NombreEquipo],0)))+1) -> - | DB8: =CY8+COUNTIFS($CZ$6:$CZ$53,CZ8,$DA$6:DA$53,"<"&DA8,$BC$6:$BC$53,INDEX(T_Equipos[Grupo],MATCH(BD8,T_Equipos[NombreEquipo],0))) -> 4 | DD8: =IF(OR(INDEX($AW$6:$AW$97,MATCH($BD8,$AV$6:$AV$97,0))="",CZ8="-"),DB8,INDEX($AW$6:$AW$97,MATCH($BD8,$AV$6:$AV$97,0))+DB8/1000) -> 4 | DE8: =IF(CZ8="-","-",COUNTIFS(DD$6:DD$53,"<"&DD8,$BC$6:$BC$53,INDEX(T_Equipos[Grupo],MATCH(BD8,T_Equipos[NombreEquipo],0)))) -> - | DF8: =CY8+COUNTIFS(CZ$6:CZ$53,CZ8,DE$6:DE$53,"<"&DE8,$BC$6:$BC$53,INDEX(T_Equipos[Grupo],MATCH(BD8,T_Equipos[NombreEquipo],0))) -> 4 | DH8: =INDEX($CY$6:$CY$53,MATCH($DO8,$BD$6:$BD$53,0)) -> 3 | DI8: =+SUMIF($BC$6:$BC$53,BC8,$BF$6:$BF$53) -> 12 | DJ8: =IF(OR(DI8=12,$AJ$99=144),COUNTIFS($DH$6:$DH$53,DH8,$BC$6:$BC$53,BC8),1) -> 1 | DK8: =DH8&"."&DJ8 -> 3.1 | DL8: {=OFFSET(Horarios!$P$3,DH8-1,0,DJ8,1)} -> 3 | DN8: 3A | DO8: =INDEX($BD$6:$BD$53,MATCH(DN8,$BM$6:$BM$53,0)) -> PO D: DEN/MKD/CZE/IRL
D9: =IF(OR(AC9="",AD9=""),"Pendiente",IF(AC9>AD9,"Local",IF(AC9<AD9,"Visitante","Empate"))) -> Local | E9: =IF(D9="Pendiente","-",INDEX($BR$6:$BR$53,MATCH($AA9,$BD$6:$BD$53,0))) -> - | F9: =IF(D9="Pendiente","-",INDEX($BR$6:$BR$53,MATCH($AF9,$BD$6:$BD$53,0))) -> P.3 (2) | H9: =IF(D9="Pendiente","-",INDEX($BX$6:$BX$53,MATCH($AA9,$BD$6:$BD$53,0))) -> - | I9: =IF(D9="Pendiente","-",INDEX($BX$6:$BX$53,MATCH($AF9,$BD$6:$BD$53,0))) -> P.3 (2) | K9: =IF(D9="Pendiente","-",INDEX($CC$6:$CC$53,MATCH($AA9,$BD$6:$BD$53,0))) -> - | L9: =IF(D9="Pendiente","-",INDEX($CC$6:$CC$53,MATCH($AF9,$BD$6:$BD$53,0))) -> P.3 (2) | N9: =IF(D9="Pendiente","-",INDEX($CF$6:$CF$53,MATCH($AA9,$BD$6:$BD$53,0))) -> - | O9: =IF(D9="Pendiente","-",INDEX($CF$6:$CF$53,MATCH($AF9,$BD$6:$BD$53,0))) -> P.3 (2) | Q9: =IF(D9="Pendiente","-",INDEX($CL$6:$CL$53,MATCH($AA9,$BD$6:$BD$53,0))) -> - | R9: =IF(D9="Pendiente","-",INDEX($CL$6:$CL$53,MATCH($AF9,$BD$6:$BD$53,0))) -> P.3 (2) | T9: =IF(D9="Pendiente","-",INDEX($CQ$6:$CQ$53,MATCH($AA9,$BD$6:$BD$53,0))) -> - | U9: =IF(D9="Pendiente","-",INDEX($CQ$6:$CQ$53,MATCH($AF9,$BD$6:$BD$53,0))) -> P.3 (2) | X9: =Horarios!C9 -> 46198.125 | Y9: =Horarios!C9 -> 46198.125 | Z9: =$Z$8 -> J3 | AA9: =A6 -> Sudáfrica | AB9: =+INDEX(Equipos!$L$2:$L$49,MATCH(WORLDCUP!AA9,Equipos!$K$2:$K$49,0)) -> 🇿🇦 | AC9: 1 | AD9: 0 | AE9: =+INDEX(Equipos!$L$2:$L$49,MATCH(WORLDCUP!AF9,Equipos!$K$2:$K$49,0)) -> 🇰🇷 | AF9: =A7 -> Corea del Sur | AG9: =IF(NOT(OR(ISBLANK(AC9),ISBLANK(AD9))),1,0) -> 1 | AH9: 54 | AI9: =AJ9&$B$4 -> 4A | AJ9: 4 | AK9: =+INDEX(Equipos!$L$2:$L$49,MATCH(WORLDCUP!AL9,Equipos!$K$2:$K$49,0)) -> 🇰🇷 | AL9: =IFERROR(INDEX($BD$6:$BD$53,MATCH(AI9,$BN$6:$BN$53,0)),"") -> Corea del Sur | AM9: =INDEX($BE$6:$BN$53,MATCH($AL9,$BD$6:$BD$53,0),MATCH(AM$5,$BE$5:$BN$5,0)) -> 2 | AN9: =INDEX($BE$6:$BN$53,MATCH($AL9,$BD$6:$BD$53,0),MATCH(AN$5,$BE$5:$BN$5,0)) -> 3 | AO9: =INDEX($BE$6:$BN$53,MATCH($AL9,$BD$6:$BD$53,0),MATCH(AO$5,$BE$5:$BN$5,0)) -> 0 | AP9: =INDEX($BE$6:$BN$53,MATCH($AL9,$BD$6:$BD$53,0),MATCH(AP$5,$BE$5:$BN$5,0)) -> 2 | AQ9: =INDEX($BE$6:$BN$53,MATCH($AL9,$BD$6:$BD$53,0),MATCH(AQ$5,$BE$5:$BN$5,0)) -> 1 | AR9: =INDEX($BE$6:$BN$53,MATCH($AL9,$BD$6:$BD$53,0),MATCH(AR$5,$BE$5:$BN$5,0)) -> 1 | AS9: =INDEX($BE$6:$BN$53,MATCH($AL9,$BD$6:$BD$53,0),MATCH(AS$5,$BE$5:$BN$5,0)) -> 2 | AT9: =INDEX($BE$6:$BN$53,MATCH($AL9,$BD$6:$BD$53,0),MATCH(AT$5,$BE$5:$BN$5,0)) -> -1 | AU9: =INDEX($DJ$6:$DJ$53,MATCH(AI9,$DN$6:$DN$53,0)) -> 1 | AV9: =INDEX($BD$6:$BD$53,MATCH(AI9,$BM$6:$BM$53,0)) -> Corea del Sur | AY9: =+A8 -> PO D: DEN/MKD/CZE/IRL | BC9: =+INDEX(T_Equipos[Grupo],MATCH(WORLDCUP!BD9,T_Equipos[NombreEquipo],0)) -> A | BD9: =+Equipos!B5 -> PO D: DEN/MKD/CZE/IRL | BE9: =+BG9*3+BH9+IF($AZ$3="No",0,INDEX($AZ$6:$AZ$97,MATCH(BD9,$AY$6:$AY$97,0))) -> 2 | BF9: =+BG9+BH9+BI9 -> 3 | BG9: =+COUNTIFS(FGLocal,BD9,Ganador,"Local")+COUNTIFS(FGVisitante,BD9,Ganador,"Visitante") -> 0 | BH9: =+COUNTIFS(FGLocal,BD9,Ganador,"Empate")+COUNTIFS(FGVisitante,BD9,Ganador,"Empate") -> 2 | BI9: =+COUNTIFS(FGVisitante,BD9,Ganador,"Local")+COUNTIFS(FGLocal,BD9,Ganador,"Visitante") -> 1 | BJ9: =+SUMIFS(FG_GolesLocal,FGLocal,BD9,Ganador,"<>"&"Pendiente",FG_GolesLocal,"<>"&"",FG_GolesVisitante,"<>"&"")+SUMIFS(FG_GolesVisitante,FGVisitante,BD9,Ganador,"<>"&"Pendiente",FG_GolesLocal,"<>"&"",FG_GolesVisitante,"<>"&"") -> 2 | BK9: =+SUMIFS(FG_GolesLocal,FGVisitante,BD9,Ganador,"<>"&"Pendiente",FG_GolesLocal,"<>"&"",FG_GolesVisitante,"<>"&"")+SUMIFS(FG_GolesVisitante,FGLocal,BD9,Ganador,"<>"&"Pendiente",FG_GolesLocal,"<>"&"",FG_GolesVisitante,"<>"&"") -> 3 | BL9: =+BJ9-BK9 -> -1 | BM9: =DB9&BC9 -> 3A | BN9: =DF9&BC9 -> 3A | BP9: =+BE9 -> 2 | BQ9: =COUNTIFS($BE$6:$BE$53,">"&BE9,$BC$6:$BC$53,INDEX(T_Equipos[Grupo],MATCH(BD9,T_Equipos[NombreEquipo],0)))+1 -> 3 | BR9: =IF(COUNTIFS($BQ$6:$BQ$53,BQ9,$BC$6:$BC$53,INDEX(T_Equipos[Grupo],MATCH(BD9,T_Equipos[NombreEquipo],0)))=1,"-","P."&BQ9&" ("&COUNTIFS($BQ$6:$BQ$53,BQ9,$BC$6:$BC$53,INDEX(T_Equipos[Grupo],MATCH(BD9,T_Equipos[NombreEquipo],0)))&")") -> P.3 (2) | BS9: =IF($BR9="-","-",COUNTIFS(FGLocal,$BD9,Ganador,"Local",Part1Empate1V,$BR9)+COUNTIFS(FGVisitante,$BD9,Ganador,"Visitante",Part1Empate1L,$BR9)) -> 0 | BT9: =IF($BR9="-","-",COUNTIFS(FGLocal,$BD9,Ganador,"Empate",Part1Empate1V,$BR9)+COUNTIFS(FGVisitante,$BD9,Ganador,"Empate",Part1Empate1L,$BR9)) -> 1 | BU9: =IF($BR9="-","-",COUNTIFS(FGLocal,$BD9,Ganador,"Visitante",Part1Empate1V,$BR9)+COUNTIFS(FGVisitante,$BD9,Ganador,"Local",Part1Empate1L,$BR9)) -> 0 | BV9: =IF($BR9="-","-",BS9*3+BT9) -> 1 | BW9: =BQ9+COUNTIFS($BR$6:$BR$53,BR9,$BV$6:BV$53,">"&BV9,$BC$6:$BC$53,INDEX(T_Equipos[Grupo],MATCH(BD9,T_Equipos[NombreEquipo],0))) -> 3 | BX9: =IF(COUNTIFS($BW$6:$BW$53,BW9,$BC$6:$BC$53,INDEX(T_Equipos[Grupo],MATCH(BD9,T_Equipos[NombreEquipo],0)))=1,"-","P."&BW9&" ("&COUNTIFS($BW$6:$BW$53,BW9,$BC$6:$BC$53,INDEX(T_Equipos[Grupo],MATCH(BD9,T_Equipos[NombreEquipo],0)))&")") -> P.3 (2) | BY9: =IF($BX9="-","-",SUMIFS(FG_GolesLocal,FGLocal,$BD9,Part1Empate2V,$BX9)+SUMIFS(FG_GolesVisitante,FGVisitante,$BD9,Part1Empate2L,$BX9)) -> 1 | BZ9: =IF($BX9="-","-",SUMIFS(FG_GolesVisitante,FGLocal,$BD9,Part1Empate2V,$BX9)+SUMIFS(FG_GolesLocal,FGVisitante,$BD9,Part1Empate2L,$BX9)) -> 1 | CA9: =IF($BX9="-","-",BY9-BZ9) -> 0 | CB9: =BW9+COUNTIFS($BX$6:$BX$53,BX9,$CA$6:CA$53,">"&CA9,$BC$6:$BC$53,INDEX(T_Equipos[Grupo],MATCH(BD9,T_Equipos[NombreEquipo],0))) -> 3 | CC9: =IF(COUNTIFS($CB$6:$CB$53,CB9,$BC$6:$BC$53,INDEX(T_Equipos[Grupo],MATCH(BD9,T_Equipos[NombreEquipo],0)))=1,"-","P."&CB9&" ("&COUNTIFS($CB$6:$CB$53,CB9,$BC$6:$BC$53,INDEX(T_Equipos[Grupo],MATCH(BD9,T_Equipos[NombreEquipo],0)))&")") -> P.3 (2) | CD9: =IF($CC9="-","-",SUMIFS(FG_GolesLocal,FGLocal,$BD9,Part1Empate3V,$CC9)+SUMIFS(FG_GolesVisitante,FGVisitante,$BD9,Part1Empate3L,$CC9)) -> 1 | CE9: =CB9+COUNTIFS($CC$6:$CC$53,CC9,$CD$6:CD$53,">"&CD9,$BC$6:$BC$53,INDEX(T_Equipos[Grupo],MATCH(BD9,T_Equipos[NombreEquipo],0))) -> 3 | CF9: =IF(COUNTIFS($CE$6:$CE$53,CE9,$BC$6:$BC$53,INDEX(T_Equipos[Grupo],MATCH(BD9,T_Equipos[NombreEquipo],0)))=1,"-","P."&CE9&" ("&COUNTIFS($CE$6:$CE$53,CE9,$BC$6:$BC$53,INDEX(T_Equipos[Grupo],MATCH(BD9,T_Equipos[NombreEquipo],0)))&")") -> P.3 (2) | CG9: =IF($CF9="-","-",COUNTIFS(FGLocal,$BD9,Ganador,"Local",Part2Empate4V,$CF9)+COUNTIFS(FGVisitante,$BD9,Ganador,"Visitante",Part2Empate4L,$CF9)) -> 0 | CH9: =IF($CF9="-","-",COUNTIFS(FGLocal,$BD9,Ganador,"Empate",Part2Empate4V,$CF9)+COUNTIFS(FGVisitante,$BD9,Ganador,"Empate",Part2Empate4L,$CF9)) -> 1 | CI9: =IF($CF9="-","-",COUNTIFS(FGLocal,$BD9,Ganador,"Visitante",Part2Empate4V,$CF9)+COUNTIFS(FGVisitante,$BD9,Ganador,"Local",Part2Empate4L,$CF9)) -> 0 | CJ9: =IF($CF9="-","-",CG9*3+CH9) -> 1 | CK9: =CE9+COUNTIFS($CF$6:$CF$53,CF9,$CJ$6:CJ$53,">"&CJ9,$BC$6:$BC$53,INDEX(T_Equipos[Grupo],MATCH(BD9,T_Equipos[NombreEquipo],0))) -> 3 | CL9: =IF(COUNTIFS($CK$6:$CK$53,CK9,$BC$6:$BC$53,INDEX(T_Equipos[Grupo],MATCH(BD9,T_Equipos[NombreEquipo],0)))=1,"-","P."&CK9&" ("&COUNTIFS($CK$6:$CK$53,CK9,$BC$6:$BC$53,INDEX(T_Equipos[Grupo],MATCH(BD9,T_Equipos[NombreEquipo],0)))&")") -> P.3 (2) | CM9: =IF($CL9="-","-",SUMIFS(FG_GolesLocal,FGLocal,$BD9,Part2Empate5V,$CL9)+SUMIFS(FG_GolesVisitante,FGVisitante,$BD9,Part2Empate5L,$CL9)) -> 1 | CN9: =IF($CL9="-","-",SUMIFS(FG_GolesVisitante,FGLocal,$BD9,Part2Empate5V,$CL9)+SUMIFS(FG_GolesLocal,FGVisitante,$BD9,Part2Empate5L,$CL9)) -> 1 | CO9: =IF($CL9="-","-",CM9-CN9) -> 0 | CP9: =CK9+COUNTIFS($CL$6:$CL$53,CL9,$CO$6:CO$53,">"&CO9,$BC$6:$BC$53,INDEX(T_Equipos[Grupo],MATCH(BD9,T_Equipos[NombreEquipo],0))) -> 3 | CQ9: =IF(COUNTIFS($CP$6:$CP$53,CP9,$BC$6:$BC$53,INDEX(T_Equipos[Grupo],MATCH(BD9,T_Equipos[NombreEquipo],0)))=1,"-","P."&CP9&" ("&COUNTIFS($CP$6:$CP$53,CP9,$BC$6:$BC$53,INDEX(T_Equipos[Grupo],MATCH(BD9,T_Equipos[NombreEquipo],0)))&")") -> P.3 (2) | CR9: =IF($CQ9="-","-",SUMIFS(FG_GolesLocal,FGLocal,$BD9,Part2Empate6V,$CQ9)+SUMIFS(FG_GolesVisitante,FGVisitante,$BD9,Part2Empate6L,$CQ9)) -> 1 | CS9: =CP9+COUNTIFS($CQ$6:$CQ$53,CQ9,$CR$6:CR$53,">"&CR9,$BC$6:$BC$53,INDEX(T_Equipos[Grupo],MATCH(BD9,T_Equipos[NombreEquipo],0))) -> 3 | CT9: =IF(COUNTIFS($CS$6:$CS$53,CS9,$BC$6:$BC$53,INDEX(T_Equipos[Grupo],MATCH(BD9,T_Equipos[NombreEquipo],0)))=1,"-","P."&CS9&" ("&COUNTIFS($CS$6:$CS$53,CS9,$BC$6:$BC$53,INDEX(T_Equipos[Grupo],MATCH(BD9,T_Equipos[NombreEquipo],0)))&")") -> P.3 (2) | CU9: =IF(CT9="-","-",BL9) -> -1 | CV9: =CS9+COUNTIFS($CT$6:$CT$53,CT9,$CU$6:CU$53,">"&CU9,$BC$6:$BC$53,INDEX(T_Equipos[Grupo],MATCH(BD9,T_Equipos[NombreEquipo],0))) -> 3 | CW9: =IF(COUNTIFS($CV$6:$CV$53,CV9,$BC$6:$BC$53,INDEX(T_Equipos[Grupo],MATCH(BD9,T_Equipos[NombreEquipo],0)))=1,"-","P."&CV9&" ("&COUNTIFS($CV$6:$CV$53,CV9,$BC$6:$BC$53,INDEX(T_Equipos[Grupo],MATCH(BD9,T_Equipos[NombreEquipo],0)))&")") -> P.3 (2) | CX9: =IF(CW9="-","-",BJ9) -> 2 | CY9: =CV9+COUNTIFS($CW$6:$CW$53,CW9,$CX$6:CX$53,">"&CX9,$BC$6:$BC$53,INDEX(T_Equipos[Grupo],MATCH(BD9,T_Equipos[NombreEquipo],0))) -> 3 | CZ9: =IF(COUNTIFS($CY$6:$CY$53,CY9,$BC$6:$BC$53,INDEX(T_Equipos[Grupo],MATCH(BD9,T_Equipos[NombreEquipo],0)))=1,"-","P."&CY9&" ("&COUNTIFS($CY$6:$CY$53,CY9,$BC$6:$BC$53,INDEX(T_Equipos[Grupo],MATCH(BD9,T_Equipos[NombreEquipo],0)))&")") -> - | DA9: =IF(CZ9="-","-",COUNTIFS(T_Equipos[Rank],"<"&INDEX(T_Equipos[Rank],MATCH(BD9,T_Equipos[NombreEquipo],0)),$BC$6:$BC$53,INDEX(T_Equipos[Grupo],MATCH(BD9,T_Equipos[NombreEquipo],0)))+1) -> - | DB9: =CY9+COUNTIFS($CZ$6:$CZ$53,CZ9,$DA$6:DA$53,"<"&DA9,$BC$6:$BC$53,INDEX(T_Equipos[Grupo],MATCH(BD9,T_Equipos[NombreEquipo],0))) -> 3 | DD9: =IF(OR(INDEX($AW$6:$AW$97,MATCH($BD9,$AV$6:$AV$97,0))="",CZ9="-"),DB9,INDEX($AW$6:$AW$97,MATCH($BD9,$AV$6:$AV$97,0))+DB9/1000) -> 3 | DE9: =IF(CZ9="-","-",COUNTIFS(DD$6:DD$53,"<"&DD9,$BC$6:$BC$53,INDEX(T_Equipos[Grupo],MATCH(BD9,T_Equipos[NombreEquipo],0)))) -> - | DF9: =CY9+COUNTIFS(CZ$6:CZ$53,CZ9,DE$6:DE$53,"<"&DE9,$BC$6:$BC$53,INDEX(T_Equipos[Grupo],MATCH(BD9,T_Equipos[NombreEquipo],0))) -> 3 | DH9: =INDEX($CY$6:$CY$53,MATCH($DO9,$BD$6:$BD$53,0)) -> 4 | DI9: =+SUMIF($BC$6:$BC$53,BC9,$BF$6:$BF$53) -> 12 | DJ9: =IF(OR(DI9=12,$AJ$99=144),COUNTIFS($DH$6:$DH$53,DH9,$BC$6:$BC$53,BC9),1) -> 1 | DK9: =DH9&"."&DJ9 -> 4.1 | DL9: {=OFFSET(Horarios!$P$3,DH9-1,0,DJ9,1)} -> 4 | DN9: 4A | DO9: =INDEX($BD$6:$BD$53,MATCH(DN9,$BM$6:$BM$53,0)) -> Corea del Sur
